Workbook

Sheet 縦7日
A1: ='1'!A1 -> GOD | M1: =A1 -> GOD
A2: 仮番号 | B2: 日付 | C2: 曜日 | D2: 台番号 | E2: 評価4以上の周期 | F2: 有効実績評価 | G2: 7日間有効実績評価平均 | H2: G数 | I2: 最大放出 | J2: 差枚 | K2: 7日間差枚 | M2: 評価4以上の周期 | N2: 実評価 | O2: AI予想 | P2: python順位 | Q2: 合算pt
A3: {=LET(n,20,TOCOL(MAKEARRAY(n,10,LAMBDA(r,c,r)),1))} -> 1 | B3: {=LET(d,SEQUENCE(8,1,TODAY()-7,1),TOCOL(MAKEARRAY(24,10,LAMBDA(r,c,IF(c<=8,INDEX(d,c),""))),1))} -> 46163 | C3: =IF(B3="","",TEXT(B3,"ddd")) -> 木 | D3: =IFERROR(__xludf.DUMMYFUNCTION("IF($B3="""","""",IFERROR(INDEX(FILTER('1'!$E:$E,'1'!$D:$D=$A3,'1'!$A:$A=$B3),1),""""))"),1164.0) -> 1164 | E3: =IFERROR(__xludf.DUMMYFUNCTION("IF($B3="""","""",IFERROR(INDEX(FILTER('1'!$G:$G,'1'!$D:$D=$A3,'1'!$A:$A=$B3),1),""""))"),5.0) -> 5 | F3: =IFERROR(__xludf.DUMMYFUNCTION("IF($B3="""","""",IFERROR(INDEX(FILTER('1'!$H:$H,'1'!$D:$D=$A3,'1'!$A:$A=$B3),1),""""))"),3.0) -> 3 | H3: =IFERROR(__xludf.DUMMYFUNCTION("IF($B3="""","""",IFERROR(INDEX(FILTER('1'!$I:$I,'1'!$D:$D=$A3,'1'!$A:$A=$B3),1),""""))"),8305.0) -> 8305 | I3: =IFERROR(__xludf.DUMMYFUNCTION("IF($B3="""","""",IFERROR(INDEX(FILTER('1'!$J:$J,'1'!$D:$D=$A3,'1'!$A:$A=$B3),1),""""))"),5331.0) -> 5331 | J3: =IFERROR(__xludf.DUMMYFUNCTION("IF($B3="""","""",IFERROR(INDEX(FILTER('1'!$K:$K,'1'!$D:$D=$A3,'1'!$A:$A=$B3),1),""""))"),800.0) -> 800 | M3: =IFERROR(__xludf.DUMMYFUNCTION("IF($B3="""","""",IFERROR(INDEX(FILTER('1'!$G:$G,'1'!$D:$D=$A3,'1'!$A:$A=$B3),1),""""))"),5.0) -> 5 | N3: =F3 -> 3 | O3: =IFERROR(__xludf.DUMMYFUNCTION("IF($B3="""","""",IFERROR(INDEX(FILTER('1'!$L:$L,'1'!$D:$D=$A3,'1'!$A:$A=$B3),1),""""))"),2.5) -> 2.5 | P3: =IFERROR(__xludf.DUMMYFUNCTION("IF($B3="""","""",IFERROR(INDEX(FILTER('1'!$M:$M,'1'!$D:$D=$A3,'1'!$A:$A=$B3),1),""""))"),6.0) -> 6 | Q3: =IFERROR(__xludf.DUMMYFUNCTION("IF($B3="""","""",IFERROR(INDEX(FILTER('1'!$O:$O,'1'!$D:$D=$A3,'1'!$A:$A=$B3),1),""""))"),3.5) -> 3.5
A4: 1 | B4: 46164 | C4: =IF(B4="","",TEXT(B4,"ddd")) -> 金 | D4: =IFERROR(__xludf.DUMMYFUNCTION("IF($B4="""","""",IFERROR(INDEX(FILTER('1'!$E:$E,'1'!$D:$D=$A4,'1'!$A:$A=$B4),1),""""))"),1164.0) -> 1164 | E4: =IFERROR(__xludf.DUMMYFUNCTION("IF($B4="""","""",IFERROR(INDEX(FILTER('1'!$G:$G,'1'!$D:$D=$A4,'1'!$A:$A=$B4),1),""""))"),6.0) -> 6 | F4: =IFERROR(__xludf.DUMMYFUNCTION("IF($B4="""","""",IFERROR(INDEX(FILTER('1'!$H:$H,'1'!$D:$D=$A4,'1'!$A:$A=$B4),1),""""))"),1.0) -> 1 | H4: =IFERROR(__xludf.DUMMYFUNCTION("IF($B4="""","""",IFERROR(INDEX(FILTER('1'!$I:$I,'1'!$D:$D=$A4,'1'!$A:$A=$B4),1),""""))"),5545.0) -> 5545 | I4: =IFERROR(__xludf.DUMMYFUNCTION("IF($B4="""","""",IFERROR(INDEX(FILTER('1'!$J:$J,'1'!$D:$D=$A4,'1'!$A:$A=$B4),1),""""))"),2034.0) -> 2034 | J4: =IFERROR(__xludf.DUMMYFUNCTION("IF($B4="""","""",IFERROR(INDEX(FILTER('1'!$K:$K,'1'!$D:$D=$A4,'1'!$A:$A=$B4),1),""""))"),-600.0) -> -600 | M4: =IFERROR(__xludf.DUMMYFUNCTION("IF($B4="""","""",IFERROR(INDEX(FILTER('1'!$G:$G,'1'!$D:$D=$A4,'1'!$A:$A=$B4),1),""""))"),6.0) -> 6 | N4: =F4 -> 1 | O4: =IFERROR(__xludf.DUMMYFUNCTION("IF($B4="""","""",IFERROR(INDEX(FILTER('1'!$L:$L,'1'!$D:$D=$A4,'1'!$A:$A=$B4),1),""""))"),2.0) -> 2 | P4: =IFERROR(__xludf.DUMMYFUNCTION("IF($B4="""","""",IFERROR(INDEX(FILTER('1'!$M:$M,'1'!$D:$D=$A4,'1'!$A:$A=$B4),1),""""))"),8.0) -> 8 | Q4: =IFERROR(__xludf.DUMMYFUNCTION("IF($B4="""","""",IFERROR(INDEX(FILTER('1'!$O:$O,'1'!$D:$D=$A4,'1'!$A:$A=$B4),1),""""))"),2.0) -> 2
A5: 1 | B5: 46165 | C5: =IF(B5="","",TEXT(B5,"ddd")) -> 土 | D5: =IFERROR(__xludf.DUMMYFUNCTION("IF($B5="""","""",IFERROR(INDEX(FILTER('1'!$E:$E,'1'!$D:$D=$A5,'1'!$A:$A=$B5),1),""""))"),1164.0) -> 1164 | E5: =IFERROR(__xludf.DUMMYFUNCTION("IF($B5="""","""",IFERROR(INDEX(FILTER('1'!$G:$G,'1'!$D:$D=$A5,'1'!$A:$A=$B5),1),""""))"),7.0) -> 7 | F5: =IFERROR(__xludf.DUMMYFUNCTION("IF($B5="""","""",IFERROR(INDEX(FILTER('1'!$H:$H,'1'!$D:$D=$A5,'1'!$A:$A=$B5),1),""""))"),4.0) -> 4 | H5: =IFERROR(__xludf.DUMMYFUNCTION("IF($B5="""","""",IFERROR(INDEX(FILTER('1'!$I:$I,'1'!$D:$D=$A5,'1'!$A:$A=$B5),1),""""))"),7505.0) -> 7505 | I5: =IFERROR(__xludf.DUMMYFUNCTION("IF($B5="""","""",IFERROR(INDEX(FILTER('1'!$J:$J,'1'!$D:$D=$A5,'1'!$A:$A=$B5),1),""""))"),5084.0) -> 5084 | J5: =IFERROR(__xludf.DUMMYFUNCTION("IF($B5="""","""",IFERROR(INDEX(FILTER('1'!$K:$K,'1'!$D:$D=$A5,'1'!$A:$A=$B5),1),""""))"),2100.0) -> 2100 | M5: =IFERROR(__xludf.DUMMYFUNCTION("IF($B5="""","""",IFERROR(INDEX(FILTER('1'!$G:$G,'1'!$D:$D=$A5,'1'!$A:$A=$B5),1),""""))"),7.0) -> 7 | N5: =F5 -> 4 | O5: =IFERROR(__xludf.DUMMYFUNCTION("IF($B5="""","""",IFERROR(INDEX(FILTER('1'!$L:$L,'1'!$D:$D=$A5,'1'!$A:$A=$B5),1),""""))"),2.0) -> 2 | P5: =IFERROR(__xludf.DUMMYFUNCTION("IF($B5="""","""",IFERROR(INDEX(FILTER('1'!$M:$M,'1'!$D:$D=$A5,'1'!$A:$A=$B5),1),""""))"),8.0) -> 8 | Q5: =IFERROR(__xludf.DUMMYFUNCTION("IF($B5="""","""",IFERROR(INDEX(FILTER('1'!$O:$O,'1'!$D:$D=$A5,'1'!$A:$A=$B5),1),""""))"),2.0) -> 2
A6: 1 | B6: 46166 | C6: =IF(B6="","",TEXT(B6,"ddd")) -> 日 | D6: =IFERROR(__xludf.DUMMYFUNCTION("IF($B6="""","""",IFERROR(INDEX(FILTER('1'!$E:$E,'1'!$D:$D=$A6,'1'!$A:$A=$B6),1),""""))"),1164.0) -> 1164 | E6: =IFERROR(__xludf.DUMMYFUNCTION("IF($B6="""","""",IFERROR(INDEX(FILTER('1'!$G:$G,'1'!$D:$D=$A6,'1'!$A:$A=$B6),1),""""))"),1.0) -> 1 | F6: =IFERROR(__xludf.DUMMYFUNCTION("IF($B6="""","""",IFERROR(INDEX(FILTER('1'!$H:$H,'1'!$D:$D=$A6,'1'!$A:$A=$B6),1),""""))"),-1.0) -> -1 | H6: =IFERROR(__xludf.DUMMYFUNCTION("IF($B6="""","""",IFERROR(INDEX(FILTER('1'!$I:$I,'1'!$D:$D=$A6,'1'!$A:$A=$B6),1),""""))"),7537.0) -> 7537 | I6: =IFERROR(__xludf.DUMMYFUNCTION("IF($B6="""","""",IFERROR(INDEX(FILTER('1'!$J:$J,'1'!$D:$D=$A6,'1'!$A:$A=$B6),1),""""))"),1921.0) -> 1921 | J6: =IFERROR(__xludf.DUMMYFUNCTION("IF($B6="""","""",IFERROR(INDEX(FILTER('1'!$K:$K,'1'!$D:$D=$A6,'1'!$A:$A=$B6),1),""""))"),-2500.0) -> -2500 | M6: =IFERROR(__xludf.DUMMYFUNCTION("IF($B6="""","""",IFERROR(INDEX(FILTER('1'!$G:$G,'1'!$D:$D=$A6,'1'!$A:$A=$B6),1),""""))"),1.0) -> 1 | N6: =F6 -> -1 | O6: =IFERROR(__xludf.DUMMYFUNCTION("IF($B6="""","""",IFERROR(INDEX(FILTER('1'!$L:$L,'1'!$D:$D=$A6,'1'!$A:$A=$B6),1),""""))"),3.0) -> 3 | P6: =IFERROR(__xludf.DUMMYFUNCTION("IF($B6="""","""",IFERROR(INDEX(FILTER('1'!$M:$M,'1'!$D:$D=$A6,'1'!$A:$A=$B6),1),""""))"),5.0) -> 5 | Q6: =IFERROR(__xludf.DUMMYFUNCTION("IF($B6="""","""",IFERROR(INDEX(FILTER('1'!$O:$O,'1'!$D:$D=$A6,'1'!$A:$A=$B6),1),""""))"),5.0) -> 5
A7: 1 | B7: 46167 | C7: =IF(B7="","",TEXT(B7,"ddd")) -> 月 | D7: =IFERROR(__xludf.DUMMYFUNCTION("IF($B7="""","""",IFERROR(INDEX(FILTER('1'!$E:$E,'1'!$D:$D=$A7,'1'!$A:$A=$B7),1),""""))"),1164.0) -> 1164 | E7: =IFERROR(__xludf.DUMMYFUNCTION("IF($B7="""","""",IFERROR(INDEX(FILTER('1'!$G:$G,'1'!$D:$D=$A7,'1'!$A:$A=$B7),1),""""))"),2.0) -> 2 | F7: =IFERROR(__xludf.DUMMYFUNCTION("IF($B7="""","""",IFERROR(INDEX(FILTER('1'!$H:$H,'1'!$D:$D=$A7,'1'!$A:$A=$B7),1),""""))"),-3.0) -> -3 | H7: =IFERROR(__xludf.DUMMYFUNCTION("IF($B7="""","""",IFERROR(INDEX(FILTER('1'!$I:$I,'1'!$D:$D=$A7,'1'!$A:$A=$B7),1),""""))"),7902.0) -> 7902 | I7: =IFERROR(__xludf.DUMMYFUNCTION("IF($B7="""","""",IFERROR(INDEX(FILTER('1'!$J:$J,'1'!$D:$D=$A7,'1'!$A:$A=$B7),1),""""))"),730.0) -> 730 | J7: =IFERROR(__xludf.DUMMYFUNCTION("IF($B7="""","""",IFERROR(INDEX(FILTER('1'!$K:$K,'1'!$D:$D=$A7,'1'!$A:$A=$B7),1),""""))"),-6000.0) -> -6000 | M7: =IFERROR(__xludf.DUMMYFUNCTION("IF($B7="""","""",IFERROR(INDEX(FILTER('1'!$G:$G,'1'!$D:$D=$A7,'1'!$A:$A=$B7),1),""""))"),2.0) -> 2 | N7: =F7 -> -3 | O7: =IFERROR(__xludf.DUMMYFUNCTION("IF($B7="""","""",IFERROR(INDEX(FILTER('1'!$L:$L,'1'!$D:$D=$A7,'1'!$A:$A=$B7),1),""""))"),1.5) -> 1.5 | P7: =IFERROR(__xludf.DUMMYFUNCTION("IF($B7="""","""",IFERROR(INDEX(FILTER('1'!$M:$M,'1'!$D:$D=$A7,'1'!$A:$A=$B7),1),""""))"),9.0) -> 9 | Q7: =IFERROR(__xludf.DUMMYFUNCTION("IF($B7="""","""",IFERROR(INDEX(FILTER('1'!$O:$O,'1'!$D:$D=$A7,'1'!$A:$A=$B7),1),""""))"),1.5) -> 1.5
A8: 1 | B8: 46168 | C8: =IF(B8="","",TEXT(B8,"ddd")) -> 火 | D8: =IFERROR(__xludf.DUMMYFUNCTION("IF($B8="""","""",IFERROR(INDEX(FILTER('1'!$E:$E,'1'!$D:$D=$A8,'1'!$A:$A=$B8),1),""""))"),1164.0) -> 1164 | E8: =IFERROR(__xludf.DUMMYFUNCTION("IF($B8="""","""",IFERROR(INDEX(FILTER('1'!$G:$G,'1'!$D:$D=$A8,'1'!$A:$A=$B8),1),""""))"),3.0) -> 3 | F8: =IFERROR(__xludf.DUMMYFUNCTION("IF($B8="""","""",IFERROR(INDEX(FILTER('1'!$H:$H,'1'!$D:$D=$A8,'1'!$A:$A=$B8),1),""""))"),-3.0) -> -3 | H8: =IFERROR(__xludf.DUMMYFUNCTION("IF($B8="""","""",IFERROR(INDEX(FILTER('1'!$I:$I,'1'!$D:$D=$A8,'1'!$A:$A=$B8),1),""""))"),6833.0) -> 6833 | I8: =IFERROR(__xludf.DUMMYFUNCTION("IF($B8="""","""",IFERROR(INDEX(FILTER('1'!$J:$J,'1'!$D:$D=$A8,'1'!$A:$A=$B8),1),""""))"),750.0) -> 750 | J8: =IFERROR(__xludf.DUMMYFUNCTION("IF($B8="""","""",IFERROR(INDEX(FILTER('1'!$K:$K,'1'!$D:$D=$A8,'1'!$A:$A=$B8),1),""""))"),-4500.0) -> -4500 | M8: =IFERROR(__xludf.DUMMYFUNCTION("IF($B8="""","""",IFERROR(INDEX(FILTER('1'!$G:$G,'1'!$D:$D=$A8,'1'!$A:$A=$B8),1),""""))"),3.0) -> 3 | N8: =F8 -> -3 | O8: =IFERROR(__xludf.DUMMYFUNCTION("IF($B8="""","""",IFERROR(INDEX(FILTER('1'!$L:$L,'1'!$D:$D=$A8,'1'!$A:$A=$B8),1),""""))"),0.5) -> 0.5 | P8: =IFERROR(__xludf.DUMMYFUNCTION("IF($B8="""","""",IFERROR(INDEX(FILTER('1'!$M:$M,'1'!$D:$D=$A8,'1'!$A:$A=$B8),1),""""))"),8.0) -> 8 | Q8: =IFERROR(__xludf.DUMMYFUNCTION("IF($B8="""","""",IFERROR(INDEX(FILTER('1'!$O:$O,'1'!$D:$D=$A8,'1'!$A:$A=$B8),1),""""))"),0.5) -> 0.5
A9: 1 | B9: 46169 | C9: =IF(B9="","",TEXT(B9,"ddd")) -> 水 | D9: =IFERROR(__xludf.DUMMYFUNCTION("IF($B9="""","""",IFERROR(INDEX(FILTER('1'!$E:$E,'1'!$D:$D=$A9,'1'!$A:$A=$B9),1),""""))"),1164.0) -> 1164 | E9: =IFERROR(__xludf.DUMMYFUNCTION("IF($B9="""","""",IFERROR(INDEX(FILTER('1'!$G:$G,'1'!$D:$D=$A9,'1'!$A:$A=$B9),1),""""))"),4.0) -> 4 | F9: =IFERROR(__xludf.DUMMYFUNCTION("IF($B9="""","""",IFERROR(INDEX(FILTER('1'!$H:$H,'1'!$D:$D=$A9,'1'!$A:$A=$B9),1),""""))"),5.0) -> 5 | G9: =IF(COUNT(F3:F9)=0,"",SUM(F3:F9)/7) -> 0.85714286 | H9: =IFERROR(__xludf.DUMMYFUNCTION("IF($B9="""","""",IFERROR(INDEX(FILTER('1'!$I:$I,'1'!$D:$D=$A9,'1'!$A:$A=$B9),1),""""))"),4235.0) -> 4235 | I9: =IFERROR(__xludf.DUMMYFUNCTION("IF($B9="""","""",IFERROR(INDEX(FILTER('1'!$J:$J,'1'!$D:$D=$A9,'1'!$A:$A=$B9),1),""""))"),7590.0) -> 7590 | J9: =IFERROR(__xludf.DUMMYFUNCTION("IF($B9="""","""",IFERROR(INDEX(FILTER('1'!$K:$K,'1'!$D:$D=$A9,'1'!$A:$A=$B9),1),""""))"),5100.0) -> 5100 | K9: {=SUM(IFERROR(VALUE(J3:J9),0))} -> -5600 | M9: =IFERROR(__xludf.DUMMYFUNCTION("IF($B9="""","""",IFERROR(INDEX(FILTER('1'!$G:$G,'1'!$D:$D=$A9,'1'!$A:$A=$B9),1),""""))"),4.0) -> 4 | N9: =F9 -> 5 | O9: =IFERROR(__xludf.DUMMYFUNCTION("IF($B9="""","""",IFERROR(INDEX(FILTER('1'!$L:$L,'1'!$D:$D=$A9,'1'!$A:$A=$B9),1),""""))"),1.0) -> 1 | P9: =IFERROR(__xludf.DUMMYFUNCTION("IF($B9="""","""",IFERROR(INDEX(FILTER('1'!$M:$M,'1'!$D:$D=$A9,'1'!$A:$A=$B9),1),""""))"),11.0) -> 11 | Q9: =IFERROR(__xludf.DUMMYFUNCTION("IF($B9="""","""",IFERROR(INDEX(FILTER('1'!$O:$O,'1'!$D:$D=$A9,'1'!$A:$A=$B9),1),""""))"),0.0) -> 0
A10: 1 | B10: 46170 | C10: =IF(B10="","",TEXT(B10,"ddd")) -> 木 | D10: =IFERROR(__xludf.DUMMYFUNCTION("IF($B10="""","""",IFERROR(INDEX(FILTER('1'!$E:$E,'1'!$D:$D=$A10,'1'!$A:$A=$B10),1),""""))"),1164.0) -> 1164 | E10: =IFERROR(__xludf.DUMMYFUNCTION("IF($B10="""","""",IFERROR(INDEX(FILTER('1'!$G:$G,'1'!$D:$D=$A10,'1'!$A:$A=$B10),1),""""))"),1.0) -> 1 | H10: =IFERROR(__xludf.DUMMYFUNCTION("IF($B10="""","""",IFERROR(INDEX(FILTER('2'!$G:$G,'2'!$D:$D=$A10,'2'!$A:$A=$B10),1),""""))"),"") | I10: =IFERROR(__xludf.DUMMYFUNCTION("IF($B10="""","""",IFERROR(INDEX(FILTER('2'!$H:$H,'2'!$D:$D=$A10,'2'!$A:$A=$B10),1),""""))"),"") | J10: =IFERROR(__xludf.DUMMYFUNCTION("IF($B10="""","""",IFERROR(INDEX(FILTER('2'!$I:$I,'2'!$D:$D=$A10,'2'!$A:$A=$B10),1),""""))"),"") | M10: =IFERROR(__xludf.DUMMYFUNCTION("IF($B10="""","""",IFERROR(INDEX(FILTER('1'!$G:$G,'1'!$D:$D=$A10,'1'!$A:$A=$B10),1),""""))"),1.0) -> 1 | N10: =F10 | O10: =IFERROR(__xludf.DUMMYFUNCTION("IF($B10="""","""",IFERROR(INDEX(FILTER('1'!$L:$L,'1'!$D:$D=$A10,'1'!$A:$A=$B10),1),""""))"),"") | P10: =IFERROR(__xludf.DUMMYFUNCTION("IF($B10="""","""",IFERROR(INDEX(FILTER('1'!$M:$M,'1'!$D:$D=$A10,'1'!$A:$A=$B10),1),""""))"),"") | Q10: =IFERROR(__xludf.DUMMYFUNCTION("IF($B10="""","""",IFERROR(INDEX(FILTER('1'!$O:$O,'1'!$D:$D=$A10,'1'!$A:$A=$B10),1),""""))"),0.0) -> 0 | R10: =D10 -> 1164
A11: 1 | N11: =F11
A12: 1 | C12: =IF(B12="","",TEXT(B12,"ddd")) | N12: =F12
A13: 2 | B13: 46163 | C13: =IF(B13="","",TEXT(B13,"ddd")) -> 木 | D13: =IFERROR(__xludf.DUMMYFUNCTION("IF($B13="""","""",IFERROR(INDEX(FILTER('1'!$U:$U,'1'!$T:$T=$A13,'1'!$A:$A=$B13),1),""""))"),1165.0) -> 1165 | E13: =IFERROR(__xludf.DUMMYFUNCTION("IF($B13="""","""",IFERROR(INDEX(FILTER('1'!$W:$W,'1'!$T:$T=$A13,'1'!$A:$A=$B13),1),""""))"),3.0) -> 3 | F13: =IFERROR(__xludf.DUMMYFUNCTION("IF($B13="""","""",IFERROR(INDEX(FILTER('1'!$X:$X,'1'!$T:$T=$A13,'1'!$A:$A=$B13),1),""""))"),4.0) -> 4 | H13: =IFERROR(__xludf.DUMMYFUNCTION("IF($B13="""","""",IFERROR(INDEX(FILTER('1'!$Y:$Y,'1'!$T:$T=$A13,'1'!$A:$A=$B13),1),""""))"),4304.0) -> 4304 | I13: =IFERROR(__xludf.DUMMYFUNCTION("IF($B13="""","""",IFERROR(INDEX(FILTER('1'!$Z:$Z,'1'!$T:$T=$A13,'1'!$A:$A=$B13),1),""""))"),6065.0) -> 6065 | J13: =IFERROR(__xludf.DUMMYFUNCTION("IF($B13="""","""",IFERROR(INDEX(FILTER('1'!$AA:$AA,'1'!$T:$T=$A13,'1'!$A:$A=$B13),1),""""))"),3000.0) -> 3000 | M13: =IFERROR(__xludf.DUMMYFUNCTION("IF($B13="""","""",IFERROR(INDEX(FILTER('1'!$W:$W,'1'!$T:$T=$A13,'1'!$A:$A=$B13),1),""""))"),3.0) -> 3 | N13: =F13 -> 4 | O13: =IFERROR(__xludf.DUMMYFUNCTION("IF($B13="""","""",IFERROR(INDEX(FILTER('1'!$AB:$AB,'1'!$T:$T=$A13,'1'!$A:$A=$B13),1),""""))"),4.0) -> 4 | P13: =IFERROR(__xludf.DUMMYFUNCTION("IF($B13="""","""",IFERROR(INDEX(FILTER('1'!$AC:$AC,'1'!$T:$T=$A13,'1'!$A:$A=$B13),1),""""))"),12.0) -> 12 | Q13: =IFERROR(__xludf.DUMMYFUNCTION("IF($B13="""","""",IFERROR(INDEX(FILTER('1'!$AE:$AE,'1'!$T:$T=$A13,'1'!$A:$A=$B13),1),""""))"),2.0) -> 2
A14: 2 | B14: 46164 | C14: =IF(B14="","",TEXT(B14,"ddd")) -> 金 | D14: =IFERROR(__xludf.DUMMYFUNCTION("IF($B14="""","""",IFERROR(INDEX(FILTER('1'!$U:$U,'1'!$T:$T=$A14,'1'!$A:$A=$B14),1),""""))"),1165.0) -> 1165 | E14: =IFERROR(__xludf.DUMMYFUNCTION("IF($B14="""","""",IFERROR(INDEX(FILTER('1'!$W:$W,'1'!$T:$T=$A14,'1'!$A:$A=$B14),1),""""))"),1.0) -> 1 | F14: =IFERROR(__xludf.DUMMYFUNCTION("IF($B14="""","""",IFERROR(INDEX(FILTER('1'!$X:$X,'1'!$T:$T=$A14,'1'!$A:$A=$B14),1),""""))"),1.0) -> 1 | H14: =IFERROR(__xludf.DUMMYFUNCTION("IF($B14="""","""",IFERROR(INDEX(FILTER('1'!$Y:$Y,'1'!$T:$T=$A14,'1'!$A:$A=$B14),1),""""))"),3250.0) -> 3250 | I14: =IFERROR(__xludf.DUMMYFUNCTION("IF($B14="""","""",IFERROR(INDEX(FILTER('1'!$Z:$Z,'1'!$T:$T=$A14,'1'!$A:$A=$B14),1),""""))"),2012.0) -> 2012 | J14: =IFERROR(__xludf.DUMMYFUNCTION("IF($B14="""","""",IFERROR(INDEX(FILTER('1'!$AA:$AA,'1'!$T:$T=$A14,'1'!$A:$A=$B14),1),""""))"),-500.0) -> -500 | M14: =IFERROR(__xludf.DUMMYFUNCTION("IF($B14="""","""",IFERROR(INDEX(FILTER('1'!$W:$W,'1'!$T:$T=$A14,'1'!$A:$A=$B14),1),""""))"),1.0) -> 1 | N14: =F14 -> 1 | O14: =IFERROR(__xludf.DUMMYFUNCTION("IF($B14="""","""",IFERROR(INDEX(FILTER('1'!$AB:$AB,'1'!$T:$T=$A14,'1'!$A:$A=$B14),1),""""))"),4.0) -> 4 | P14: =IFERROR(__xludf.DUMMYFUNCTION("IF($B14="""","""",IFERROR(INDEX(FILTER('1'!$AC:$AC,'1'!$T:$T=$A14,'1'!$A:$A=$B14),1),""""))"),6.0) -> 6 | Q14: =IFERROR(__xludf.DUMMYFUNCTION("IF($B14="""","""",IFERROR(INDEX(FILTER('1'!$AE:$AE,'1'!$T:$T=$A14,'1'!$A:$A=$B14),1),""""))"),5.0) -> 5
A15: 2 | B15: 46165 | C15: =IF(B15="","",TEXT(B15,"ddd")) -> 土 | D15: =IFERROR(__xludf.DUMMYFUNCTION("IF($B15="""","""",IFERROR(INDEX(FILTER('1'!$U:$U,'1'!$T:$T=$A15,'1'!$A:$A=$B15),1),""""))"),1165.0) -> 1165 | E15: =IFERROR(__xludf.DUMMYFUNCTION("IF($B15="""","""",IFERROR(INDEX(FILTER('1'!$W:$W,'1'!$T:$T=$A15,'1'!$A:$A=$B15),1),""""))"),2.0) -> 2 | F15: =IFERROR(__xludf.DUMMYFUNCTION("IF($B15="""","""",IFERROR(INDEX(FILTER('1'!$X:$X,'1'!$T:$T=$A15,'1'!$A:$A=$B15),1),""""))"),-3.0) -> -3 | H15: =IFERROR(__xludf.DUMMYFUNCTION("IF($B15="""","""",IFERROR(INDEX(FILTER('1'!$Y:$Y,'1'!$T:$T=$A15,'1'!$A:$A=$B15),1),""""))"),6915.0) -> 6915 | I15: =IFERROR(__xludf.DUMMYFUNCTION("IF($B15="""","""",IFERROR(INDEX(FILTER('1'!$Z:$Z,'1'!$T:$T=$A15,'1'!$A:$A=$B15),1),""""))"),1064.0) -> 1064 | J15: =IFERROR(__xludf.DUMMYFUNCTION("IF($B15="""","""",IFERROR(INDEX(FILTER('1'!$AA:$AA,'1'!$T:$T=$A15,'1'!$A:$A=$B15),1),""""))"),-4500.0) -> -4500 | M15: =IFERROR(__xludf.DUMMYFUNCTION("IF($B15="""","""",IFERROR(INDEX(FILTER('1'!$W:$W,'1'!$T:$T=$A15,'1'!$A:$A=$B15),1),""""))"),2.0) -> 2 | N15: =F15 -> -3 | O15: =IFERROR(__xludf.DUMMYFUNCTION("IF($B15="""","""",IFERROR(INDEX(FILTER('1'!$AB:$AB,'1'!$T:$T=$A15,'1'!$A:$A=$B15),1),""""))"),3.0) -> 3 | P15: =IFERROR(__xludf.DUMMYFUNCTION("IF($B15="""","""",IFERROR(INDEX(FILTER('1'!$AC:$AC,'1'!$T:$T=$A15,'1'!$A:$A=$B15),1),""""))"),11.0) -> 11 | Q15: =IFERROR(__xludf.DUMMYFUNCTION("IF($B15="""","""",IFERROR(INDEX(FILTER('1'!$AE:$AE,'1'!$T:$T=$A15,'1'!$A:$A=$B15),1),""""))"),2.0) -> 2
A16: 2 | B16: 46166 | C16: =IF(B16="","",TEXT(B16,"ddd")) -> 日 | D16: =IFERROR(__xludf.DUMMYFUNCTION("IF($B16="""","""",IFERROR(INDEX(FILTER('1'!$U:$U,'1'!$T:$T=$A16,'1'!$A:$A=$B16),1),""""))"),1165.0) -> 1165 | E16: =IFERROR(__xludf.DUMMYFUNCTION("IF($B16="""","""",IFERROR(INDEX(FILTER('1'!$W:$W,'1'!$T:$T=$A16,'1'!$A:$A=$B16),1),""""))"),3.0) -> 3 | F16: =IFERROR(__xludf.DUMMYFUNCTION("IF($B16="""","""",IFERROR(INDEX(FILTER('1'!$X:$X,'1'!$T:$T=$A16,'1'!$A:$A=$B16),1),""""))"),-3.0) -> -3 | H16: =IFERROR(__xludf.DUMMYFUNCTION("IF($B16="""","""",IFERROR(INDEX(FILTER('1'!$Y:$Y,'1'!$T:$T=$A16,'1'!$A:$A=$B16),1),""""))"),7255.0) -> 7255 | I16: =IFERROR(__xludf.DUMMYFUNCTION("IF($B16="""","""",IFERROR(INDEX(FILTER('1'!$Z:$Z,'1'!$T:$T=$A16,'1'!$A:$A=$B16),1),""""))"),931.0) -> 931 | J16: =IFERROR(__xludf.DUMMYFUNCTION("IF($B16="""","""",IFERROR(INDEX(FILTER('1'!$AA:$AA,'1'!$T:$T=$A16,'1'!$A:$A=$B16),1),""""))"),-5000.0) -> -5000 | M16: =IFERROR(__xludf.DUMMYFUNCTION("IF($B16="""","""",IFERROR(INDEX(FILTER('1'!$W:$W,'1'!$T:$T=$A16,'1'!$A:$A=$B16),1),""""))"),3.0) -> 3 | N16: =F16 -> -3 | O16: =IFERROR(__xludf.DUMMYFUNCTION("IF($B16="""","""",IFERROR(INDEX(FILTER('1'!$AB:$AB,'1'!$T:$T=$A16,'1'!$A:$A=$B16),1),""""))"),2.5) -> 2.5 | P16: =IFERROR(__xludf.DUMMYFUNCTION("IF($B16="""","""",IFERROR(INDEX(FILTER('1'!$AC:$AC,'1'!$T:$T=$A16,'1'!$A:$A=$B16),1),""""))"),12.0) -> 12 | Q16: =IFERROR(__xludf.DUMMYFUNCTION("IF($B16="""","""",IFERROR(INDEX(FILTER('1'!$AE:$AE,'1'!$T:$T=$A16,'1'!$A:$A=$B16),1),""""))"),0.5) -> 0.5
A17: 2 | B17: 46167 | C17: =IF(B17="","",TEXT(B17,"ddd")) -> 月 | D17: =IFERROR(__xludf.DUMMYFUNCTION("IF($B17="""","""",IFERROR(INDEX(FILTER('1'!$U:$U,'1'!$T:$T=$A17,'1'!$A:$A=$B17),1),""""))"),1165.0) -> 1165 | E17: =IFERROR(__xludf.DUMMYFUNCTION("IF($B17="""","""",IFERROR(INDEX(FILTER('1'!$W:$W,'1'!$T:$T=$A17,'1'!$A:$A=$B17),1),""""))"),4.0) -> 4 | F17: =IFERROR(__xludf.DUMMYFUNCTION("IF($B17="""","""",IFERROR(INDEX(FILTER('1'!$X:$X,'1'!$T:$T=$A17,'1'!$A:$A=$B17),1),""""))"),-2.0) -> -2 | H17: =IFERROR(__xludf.DUMMYFUNCTION("IF($B17="""","""",IFERROR(INDEX(FILTER('1'!$Y:$Y,'1'!$T:$T=$A17,'1'!$A:$A=$B17),1),""""))"),5432.0) -> 5432 | I17: =IFERROR(__xludf.DUMMYFUNCTION("IF($B17="""","""",IFERROR(INDEX(FILTER('1'!$Z:$Z,'1'!$T:$T=$A17,'1'!$A:$A=$B17),1),""""))"),1167.0) -> 1167 | J17: =IFERROR(__xludf.DUMMYFUNCTION("IF($B17="""","""",IFERROR(INDEX(FILTER('1'!$AA:$AA,'1'!$T:$T=$A17,'1'!$A:$A=$B17),1),""""))"),-4000.0) -> -4000 | M17: =IFERROR(__xludf.DUMMYFUNCTION("IF($B17="""","""",IFERROR(INDEX(FILTER('1'!$W:$W,'1'!$T:$T=$A17,'1'!$A:$A=$B17),1),""""))"),4.0) -> 4 | N17: =F17 -> -2 | O17: =IFERROR(__xludf.DUMMYFUNCTION("IF($B17="""","""",IFERROR(INDEX(FILTER('1'!$AB:$AB,'1'!$T:$T=$A17,'1'!$A:$A=$B17),1),""""))"),1.0) -> 1 | P17: =IFERROR(__xludf.DUMMYFUNCTION("IF($B17="""","""",IFERROR(INDEX(FILTER('1'!$AC:$AC,'1'!$T:$T=$A17,'1'!$A:$A=$B17),1),""""))"),11.0) -> 11 | Q17: =IFERROR(__xludf.DUMMYFUNCTION("IF($B17="""","""",IFERROR(INDEX(FILTER('1'!$AE:$AE,'1'!$T:$T=$A17,'1'!$A:$A=$B17),1),""""))"),0.0) -> 0
A18: 2 | B18: 46168 | C18: =IF(B18="","",TEXT(B18,"ddd")) -> 火 | D18: =IFERROR(__xludf.DUMMYFUNCTION("IF($B18="""","""",IFERROR(INDEX(FILTER('1'!$U:$U,'1'!$T:$T=$A18,'1'!$A:$A=$B18),1),""""))"),1165.0) -> 1165 | E18: =IFERROR(__xludf.DUMMYFUNCTION("IF($B18="""","""",IFERROR(INDEX(FILTER('1'!$W:$W,'1'!$T:$T=$A18,'1'!$A:$A=$B18),1),""""))"),5.0) -> 5 | F18: =IFERROR(__xludf.DUMMYFUNCTION("IF($B18="""","""",IFERROR(INDEX(FILTER('1'!$X:$X,'1'!$T:$T=$A18,'1'!$A:$A=$B18),1),""""))"),1.0) -> 1 | H18: =IFERROR(__xludf.DUMMYFUNCTION("IF($B18="""","""",IFERROR(INDEX(FILTER('1'!$Y:$Y,'1'!$T:$T=$A18,'1'!$A:$A=$B18),1),""""))"),4177.0) -> 4177 | I18: =IFERROR(__xludf.DUMMYFUNCTION("IF($B18="""","""",IFERROR(INDEX(FILTER('1'!$Z:$Z,'1'!$T:$T=$A18,'1'!$A:$A=$B18),1),""""))"),1449.0) -> 1449 | J18: =IFERROR(__xludf.DUMMYFUNCTION("IF($B18="""","""",IFERROR(INDEX(FILTER('1'!$AA:$AA,'1'!$T:$T=$A18,'1'!$A:$A=$B18),1),""""))"),-2000.0) -> -2000 | M18: =IFERROR(__xludf.DUMMYFUNCTION("IF($B18="""","""",IFERROR(INDEX(FILTER('1'!$W:$W,'1'!$T:$T=$A18,'1'!$A:$A=$B18),1),""""))"),5.0) -> 5 | N18: =F18 -> 1 | O18: =IFERROR(__xludf.DUMMYFUNCTION("IF($B18="""","""",IFERROR(INDEX(FILTER('1'!$AB:$AB,'1'!$T:$T=$A18,'1'!$A:$A=$B18),1),""""))"),-0.5) -> -0.5 | P18: =IFERROR(__xludf.DUMMYFUNCTION("IF($B18="""","""",IFERROR(INDEX(FILTER('1'!$AC:$AC,'1'!$T:$T=$A18,'1'!$A:$A=$B18),1),""""))"),10.0) -> 10 | Q18: =IFERROR(__xludf.DUMMYFUNCTION("IF($B18="""","""",IFERROR(INDEX(FILTER('1'!$AE:$AE,'1'!$T:$T=$A18,'1'!$A:$A=$B18),1),""""))"),-1.5) -> -1.5
A19: 2 | B19: 46169 | C19: =IF(B19="","",TEXT(B19,"ddd")) -> 水 | D19: =IFERROR(__xludf.DUMMYFUNCTION("IF($B19="""","""",IFERROR(INDEX(FILTER('1'!$U:$U,'1'!$T:$T=$A19,'1'!$A:$A=$B19),1),""""))"),1165.0) -> 1165 | E19: =IFERROR(__xludf.DUMMYFUNCTION("IF($B19="""","""",IFERROR(INDEX(FILTER('1'!$W:$W,'1'!$T:$T=$A19,'1'!$A:$A=$B19),1),""""))"),6.0) -> 6 | F19: =IFERROR(__xludf.DUMMYFUNCTION("IF($B19="""","""",IFERROR(INDEX(FILTER('1'!$X:$X,'1'!$T:$T=$A19,'1'!$A:$A=$B19),1),""""))"),4.0) -> 4 | G19: =IF(COUNT(F13:F19)=0,"",SUM(F13:F19)/7) -> 0.28571429 | H19: =IFERROR(__xludf.DUMMYFUNCTION("IF($B19="""","""",IFERROR(INDEX(FILTER('1'!$Y:$Y,'1'!$T:$T=$A19,'1'!$A:$A=$B19),1),""""))"),5989.0) -> 5989 | I19: =IFERROR(__xludf.DUMMYFUNCTION("IF($B19="""","""",IFERROR(INDEX(FILTER('1'!$Z:$Z,'1'!$T:$T=$A19,'1'!$A:$A=$B19),1),""""))"),6705.0) -> 6705 | J19: =IFERROR(__xludf.DUMMYFUNCTION("IF($B19="""","""",IFERROR(INDEX(FILTER('1'!$AA:$AA,'1'!$T:$T=$A19,'1'!$A:$A=$B19),1),""""))"),5500.0) -> 5500 | K19: {=SUM(IFERROR(VALUE(J13:J19),0))} -> -7500 | M19: =IFERROR(__xludf.DUMMYFUNCTION("IF($B19="""","""",IFERROR(INDEX(FILTER('1'!$W:$W,'1'!$T:$T=$A19,'1'!$A:$A=$B19),1),""""))"),6.0) -> 6 | N19: =F19 -> 4 | O19: =IFERROR(__xludf.DUMMYFUNCTION("IF($B19="""","""",IFERROR(INDEX(FILTER('1'!$AB:$AB,'1'!$T:$T=$A19,'1'!$A:$A=$B19),1),""""))"),0.5) -> 0.5 | P19: =IFERROR(__xludf.DUMMYFUNCTION("IF($B19="""","""",IFERROR(INDEX(FILTER('1'!$AC:$AC,'1'!$T:$T=$A19,'1'!$A:$A=$B19),1),""""))"),12.0) -> 12 | Q19: =IFERROR(__xludf.DUMMYFUNCTION("IF($B19="""","""",IFERROR(INDEX(FILTER('1'!$AE:$AE,'1'!$T:$T=$A19,'1'!$A:$A=$B19),1),""""))"),-1.5) -> -1.5
A20: 2 | B20: 46170 | C20: =IF(B20="","",TEXT(B20,"ddd")) -> 木 | D20: =IFERROR(__xludf.DUMMYFUNCTION("IF($B20="""","""",IFERROR(INDEX(FILTER('1'!$U:$U,'1'!$T:$T=$A20,'1'!$A:$A=$B20),1),""""))"),1165.0) -> 1165 | E20: =IFERROR(__xludf.DUMMYFUNCTION("IF($B20="""","""",IFERROR(INDEX(FILTER('1'!$W:$W,'1'!$T:$T=$A20,'1'!$A:$A=$B20),1),""""))"),1.0) -> 1 | H20: =IFERROR(__xludf.DUMMYFUNCTION("IF($B20="""","""",IFERROR(INDEX(FILTER('2'!$V:$V,'2'!$S:$S=$A20,'2'!$A:$A=$B20),1),""""))"),"") | I20: =IFERROR(__xludf.DUMMYFUNCTION("IF($B20="""","""",IFERROR(INDEX(FILTER('2'!$W:$W,'2'!$S:$S=$A20,'2'!$A:$A=$B20),1),""""))"),"") | M20: =IFERROR(__xludf.DUMMYFUNCTION("IF($B20="""","""",IFERROR(INDEX(FILTER('1'!$W:$W,'1'!$T:$T=$A20,'1'!$A:$A=$B20),1),""""))"),1.0) -> 1 | N20: =F20 | O20: =IFERROR(__xludf.DUMMYFUNCTION("IF($B20="""","""",IFERROR(INDEX(FILTER('1'!$AB:$AB,'1'!$T:$T=$A20,'1'!$A:$A=$B20),1),""""))"),"") | P20: =IFERROR(__xludf.DUMMYFUNCTION("IF($B20="""","""",IFERROR(INDEX(FILTER('1'!$AC:$AC,'1'!$T:$T=$A20,'1'!$A:$A=$B20),1),""""))"),"") | Q20: =IFERROR(__xludf.DUMMYFUNCTION("IF($B20="""","""",IFERROR(INDEX(FILTER('1'!$AE:$AE,'1'!$T:$T=$A20,'1'!$A:$A=$B20),1),""""))"),0.0) -> 0 | R20: =D20 -> 1165
A21: 2 | H21: =IFERROR(__xludf.DUMMYFUNCTION("IF($B21="""","""",IFERROR(INDEX(FILTER('1'!$X:$X,'1'!$T:$T=$A21,'1'!$A:$A=$B21),1),""""))"),"") | N21: =F21
A22: 2 | C22: =IF(B22="","",TEXT(B22,"ddd")) | N22: =F22
A23: 3 | B23: 46163 | C23: =IF(B23="","",TEXT(B23,"ddd")) -> 木 | D23: =IFERROR(__xludf.DUMMYFUNCTION("IF($B23="""","""",IFERROR(INDEX(FILTER('1'!$AK:$AK,'1'!$AJ:$AJ=$A23,'1'!$A:$A=$B23),1),""""))"),1166.0) -> 1166 | E23: =IFERROR(__xludf.DUMMYFUNCTION("IF($B23="""","""",IFERROR(INDEX(FILTER('1'!$AM:$AM,'1'!$AJ:$AJ=$A23,'1'!$A:$A=$B23),1),""""))"),2.0) -> 2 | F23: =IFERROR(__xludf.DUMMYFUNCTION("IF($B23="""","""",IFERROR(INDEX(FILTER('1'!$AN:$AN,'1'!$AJ:$AJ=$A23,'1'!$A:$A=$B23),1),""""))"),2.0) -> 2 | H23: =IFERROR(__xludf.DUMMYFUNCTION("IF($B23="""","""",IFERROR(INDEX(FILTER('1'!$AO:$AO,'1'!$AJ:$AJ=$A23,'1'!$A:$A=$B23),1),""""))"),6204.0) -> 6204 | I23: =IFERROR(__xludf.DUMMYFUNCTION("IF($B23="""","""",IFERROR(INDEX(FILTER('1'!$AP:$AP,'1'!$AJ:$AJ=$A23,'1'!$A:$A=$B23),1),""""))"),2772.0) -> 2772 | J23: =IFERROR(__xludf.DUMMYFUNCTION("IF($B23="""","""",IFERROR(INDEX(FILTER('1'!$AQ:$AQ,'1'!$AJ:$AJ=$A23,'1'!$A:$A=$B23),1),""""))"),-100.0) -> -100 | M23: =IFERROR(__xludf.DUMMYFUNCTION("IF($B23="""","""",IFERROR(INDEX(FILTER('1'!$AM:$AM,'1'!$AJ:$AJ=$A23,'1'!$A:$A=$B23),1),""""))"),2.0) -> 2 | N23: =F23 -> 2 | O23: =IFERROR(__xludf.DUMMYFUNCTION("IF($B23="""","""",IFERROR(INDEX(FILTER('1'!$AR:$AR,'1'!$AJ:$AJ=$A23,'1'!$A:$A=$B23),1),""""))"),1.0) -> 1 | P23: =IFERROR(__xludf.DUMMYFUNCTION("IF($B23="""","""",IFERROR(INDEX(FILTER('1'!$AS:$AS,'1'!$AJ:$AJ=$A23,'1'!$A:$A=$B23),1),""""))"),8.0) -> 8 | Q23: =IFERROR(__xludf.DUMMYFUNCTION("IF($B23="""","""",IFERROR(INDEX(FILTER('1'!$AU:$AU,'1'!$AJ:$AJ=$A23,'1'!$A:$A=$B23),1),""""))"),1.0) -> 1
A24: 3 | B24: 46164 | C24: =IF(B24="","",TEXT(B24,"ddd")) -> 金 | D24: =IFERROR(__xludf.DUMMYFUNCTION("IF($B24="""","""",IFERROR(INDEX(FILTER('1'!$AK:$AK,'1'!$AJ:$AJ=$A24,'1'!$A:$A=$B24),1),""""))"),1166.0) -> 1166 | E24: =IFERROR(__xludf.DUMMYFUNCTION("IF($B24="""","""",IFERROR(INDEX(FILTER('1'!$AM:$AM,'1'!$AJ:$AJ=$A24,'1'!$A:$A=$B24),1),""""))"),3.0) -> 3 | F24: =IFERROR(__xludf.DUMMYFUNCTION("IF($B24="""","""",IFERROR(INDEX(FILTER('1'!$AN:$AN,'1'!$AJ:$AJ=$A24,'1'!$A:$A=$B24),1),""""))"),1.0) -> 1 | H24: =IFERROR(__xludf.DUMMYFUNCTION("IF($B24="""","""",IFERROR(INDEX(FILTER('1'!$AO:$AO,'1'!$AJ:$AJ=$A24,'1'!$A:$A=$B24),1),""""))"),2565.0) -> 2565 | I24: =IFERROR(__xludf.DUMMYFUNCTION("IF($B24="""","""",IFERROR(INDEX(FILTER('1'!$AP:$AP,'1'!$AJ:$AJ=$A24,'1'!$A:$A=$B24),1),""""))"),1056.0) -> 1056 | J24: =IFERROR(__xludf.DUMMYFUNCTION("IF($B24="""","""",IFERROR(INDEX(FILTER('1'!$AQ:$AQ,'1'!$AJ:$AJ=$A24,'1'!$A:$A=$B24),1),""""))"),-1100.0) -> -1100 | M24: =IFERROR(__xludf.DUMMYFUNCTION("IF($B24="""","""",IFERROR(INDEX(FILTER('1'!$AM:$AM,'1'!$AJ:$AJ=$A24,'1'!$A:$A=$B24),1),""""))"),3.0) -> 3 | N24: =F24 -> 1 | O24: =IFERROR(__xludf.DUMMYFUNCTION("IF($B24="""","""",IFERROR(INDEX(FILTER('1'!$AR:$AR,'1'!$AJ:$AJ=$A24,'1'!$A:$A=$B24),1),""""))"),1.5) -> 1.5 | P24: =IFERROR(__xludf.DUMMYFUNCTION("IF($B24="""","""",IFERROR(INDEX(FILTER('1'!$AS:$AS,'1'!$AJ:$AJ=$A24,'1'!$A:$A=$B24),1),""""))"),9.0) -> 9 | Q24: =IFERROR(__xludf.DUMMYFUNCTION("IF($B24="""","""",IFERROR(INDEX(FILTER('1'!$AU:$AU,'1'!$AJ:$AJ=$A24,'1'!$A:$A=$B24),1),""""))"),1.5) -> 1.5
A25: 3 | B25: 46165 | C25: =IF(B25="","",TEXT(B25,"ddd")) -> 土 | D25: =IFERROR(__xludf.DUMMYFUNCTION("IF($B25="""","""",IFERROR(INDEX(FILTER('1'!$AK:$AK,'1'!$AJ:$AJ=$A25,'1'!$A:$A=$B25),1),""""))"),1166.0) -> 1166 | E25: =IFERROR(__xludf.DUMMYFUNCTION("IF($B25="""","""",IFERROR(INDEX(FILTER('1'!$AM:$AM,'1'!$AJ:$AJ=$A25,'1'!$A:$A=$B25),1),""""))"),4.0) -> 4 | F25: =IFERROR(__xludf.DUMMYFUNCTION("IF($B25="""","""",IFERROR(INDEX(FILTER('1'!$AN:$AN,'1'!$AJ:$AJ=$A25,'1'!$A:$A=$B25),1),""""))"),-2.0) -> -2 | H25: =IFERROR(__xludf.DUMMYFUNCTION("IF($B25="""","""",IFERROR(INDEX(FILTER('1'!$AO:$AO,'1'!$AJ:$AJ=$A25,'1'!$A:$A=$B25),1),""""))"),8204.0) -> 8204 | I25: =IFERROR(__xludf.DUMMYFUNCTION("IF($B25="""","""",IFERROR(INDEX(FILTER('1'!$AP:$AP,'1'!$AJ:$AJ=$A25,'1'!$A:$A=$B25),1),""""))"),1314.0) -> 1314 | J25: =IFERROR(__xludf.DUMMYFUNCTION("IF($B25="""","""",IFERROR(INDEX(FILTER('1'!$AQ:$AQ,'1'!$AJ:$AJ=$A25,'1'!$A:$A=$B25),1),""""))"),-6000.0) -> -6000 | M25: =IFERROR(__xludf.DUMMYFUNCTION("IF($B25="""","""",IFERROR(INDEX(FILTER('1'!$AM:$AM,'1'!$AJ:$AJ=$A25,'1'!$A:$A=$B25),1),""""))"),4.0) -> 4 | N25: =F25 -> -2 | O25: =IFERROR(__xludf.DUMMYFUNCTION("IF($B25="""","""",IFERROR(INDEX(FILTER('1'!$AR:$AR,'1'!$AJ:$AJ=$A25,'1'!$A:$A=$B25),1),""""))"),0.5) -> 0.5 | P25: =IFERROR(__xludf.DUMMYFUNCTION("IF($B25="""","""",IFERROR(INDEX(FILTER('1'!$AS:$AS,'1'!$AJ:$AJ=$A25,'1'!$A:$A=$B25),1),""""))"),9.0) -> 9 | Q25: =IFERROR(__xludf.DUMMYFUNCTION("IF($B25="""","""",IFERROR(INDEX(FILTER('1'!$AU:$AU,'1'!$AJ:$AJ=$A25,'1'!$A:$A=$B25),1),""""))"),0.5) -> 0.5
A26: 3 | B26: 46166 | C26: =IF(B26="","",TEXT(B26,"ddd")) -> 日 | D26: =IFERROR(__xludf.DUMMYFUNCTION("IF($B26="""","""",IFERROR(INDEX(FILTER('1'!$AK:$AK,'1'!$AJ:$AJ=$A26,'1'!$A:$A=$B26),1),""""))"),1166.0) -> 1166 | E26: =IFERROR(__xludf.DUMMYFUNCTION("IF($B26="""","""",IFERROR(INDEX(FILTER('1'!$AM:$AM,'1'!$AJ:$AJ=$A26,'1'!$A:$A=$B26),1),""""))"),5.0) -> 5 | F26: =IFERROR(__xludf.DUMMYFUNCTION("IF($B26="""","""",IFERROR(INDEX(FILTER('1'!$AN:$AN,'1'!$AJ:$AJ=$A26,'1'!$A:$A=$B26),1),""""))"),1.0) -> 1 | H26: =IFERROR(__xludf.DUMMYFUNCTION("IF($B26="""","""",IFERROR(INDEX(FILTER('1'!$AO:$AO,'1'!$AJ:$AJ=$A26,'1'!$A:$A=$B26),1),""""))"),6531.0) -> 6531 | I26: =IFERROR(__xludf.DUMMYFUNCTION("IF($B26="""","""",IFERROR(INDEX(FILTER('1'!$AP:$AP,'1'!$AJ:$AJ=$A26,'1'!$A:$A=$B26),1),""""))"),2599.0) -> 2599 | J26: =IFERROR(__xludf.DUMMYFUNCTION("IF($B26="""","""",IFERROR(INDEX(FILTER('1'!$AQ:$AQ,'1'!$AJ:$AJ=$A26,'1'!$A:$A=$B26),1),""""))"),-2000.0) -> -2000 | M26: =IFERROR(__xludf.DUMMYFUNCTION("IF($B26="""","""",IFERROR(INDEX(FILTER('1'!$AM:$AM,'1'!$AJ:$AJ=$A26,'1'!$A:$A=$B26),1),""""))"),5.0) -> 5 | N26: =F26 -> 1 | O26: =IFERROR(__xludf.DUMMYFUNCTION("IF($B26="""","""",IFERROR(INDEX(FILTER('1'!$AR:$AR,'1'!$AJ:$AJ=$A26,'1'!$A:$A=$B26),1),""""))"),-0.5) -> -0.5 | P26: =IFERROR(__xludf.DUMMYFUNCTION("IF($B26="""","""",IFERROR(INDEX(FILTER('1'!$AS:$AS,'1'!$AJ:$AJ=$A26,'1'!$A:$A=$B26),1),""""))"),13.0) -> 13 | Q26: =IFERROR(__xludf.DUMMYFUNCTION("IF($B26="""","""",IFERROR(INDEX(FILTER('1'!$AU:$AU,'1'!$AJ:$AJ=$A26,'1'!$A:$A=$B26),1),""""))"),-2.5) -> -2.5
A27: 3 | B27: 46167 | C27: =IF(B27="","",TEXT(B27,"ddd")) -> 月 | D27: =IFERROR(__xludf.DUMMYFUNCTION("IF($B27="""","""",IFERROR(INDEX(FILTER('1'!$AK:$AK,'1'!$AJ:$AJ=$A27,'1'!$A:$A=$B27),1),""""))"),1166.0) -> 1166 | E27: =IFERROR(__xludf.DUMMYFUNCTION("IF($B27="""","""",IFERROR(INDEX(FILTER('1'!$AM:$AM,'1'!$AJ:$AJ=$A27,'1'!$A:$A=$B27),1),""""))"),6.0) -> 6 | F27: =IFERROR(__xludf.DUMMYFUNCTION("IF($B27="""","""",IFERROR(INDEX(FILTER('1'!$AN:$AN,'1'!$AJ:$AJ=$A27,'1'!$A:$A=$B27),1),""""))"),-3.0) -> -3 | H27: =IFERROR(__xludf.DUMMYFUNCTION("IF($B27="""","""",IFERROR(INDEX(FILTER('1'!$AO:$AO,'1'!$AJ:$AJ=$A27,'1'!$A:$A=$B27),1),""""))"),2957.0) -> 2957 | I27: =IFERROR(__xludf.DUMMYFUNCTION("IF($B27="""","""",IFERROR(INDEX(FILTER('1'!$AP:$AP,'1'!$AJ:$AJ=$A27,'1'!$A:$A=$B27),1),""""))"),393.0) -> 393 | J27: =IFERROR(__xludf.DUMMYFUNCTION("IF($B27="""","""",IFERROR(INDEX(FILTER('1'!$AQ:$AQ,'1'!$AJ:$AJ=$A27,'1'!$A:$A=$B27),1),""""))"),-4000.0) -> -4000 | M27: =IFERROR(__xludf.DUMMYFUNCTION("IF($B27="""","""",IFERROR(INDEX(FILTER('1'!$AM:$AM,'1'!$AJ:$AJ=$A27,'1'!$A:$A=$B27),1),""""))"),6.0) -> 6 | N27: =F27 -> -3 | O27: =IFERROR(__xludf.DUMMYFUNCTION("IF($B27="""","""",IFERROR(INDEX(FILTER('1'!$AR:$AR,'1'!$AJ:$AJ=$A27,'1'!$A:$A=$B27),1),""""))"),1.0) -> 1 | P27: =IFERROR(__xludf.DUMMYFUNCTION("IF($B27="""","""",IFERROR(INDEX(FILTER('1'!$AS:$AS,'1'!$AJ:$AJ=$A27,'1'!$A:$A=$B27),1),""""))"),10.0) -> 10 | Q27: =IFERROR(__xludf.DUMMYFUNCTION("IF($B27="""","""",IFERROR(INDEX(FILTER('1'!$AU:$AU,'1'!$AJ:$AJ=$A27,'1'!$A:$A=$B27),1),""""))"),0.0) -> 0
A28: 3 | B28: 46168 | C28: =IF(B28="","",TEXT(B28,"ddd")) -> 火 | D28: =IFERROR(__xludf.DUMMYFUNCTION("IF($B28="""","""",IFERROR(INDEX(FILTER('1'!$AK:$AK,'1'!$AJ:$AJ=$A28,'1'!$A:$A=$B28),1),""""))"),1166.0) -> 1166 | E28: =IFERROR(__xludf.DUMMYFUNCTION("IF($B28="""","""",IFERROR(INDEX(FILTER('1'!$AM:$AM,'1'!$AJ:$AJ=$A28,'1'!$A:$A=$B28),1),""""))"),7.0) -> 7 | F28: =IFERROR(__xludf.DUMMYFUNCTION("IF($B28="""","""",IFERROR(INDEX(FILTER('1'!$AN:$AN,'1'!$AJ:$AJ=$A28,'1'!$A:$A=$B28),1),""""))"),4.0) -> 4 | H28: =IFERROR(__xludf.DUMMYFUNCTION("IF($B28="""","""",IFERROR(INDEX(FILTER('1'!$AO:$AO,'1'!$AJ:$AJ=$A28,'1'!$A:$A=$B28),1),""""))"),4239.0) -> 4239 | I28: =IFERROR(__xludf.DUMMYFUNCTION("IF($B28="""","""",IFERROR(INDEX(FILTER('1'!$AP:$AP,'1'!$AJ:$AJ=$A28,'1'!$A:$A=$B28),1),""""))"),5480.0) -> 5480 | J28: =IFERROR(__xludf.DUMMYFUNCTION("IF($B28="""","""",IFERROR(INDEX(FILTER('1'!$AQ:$AQ,'1'!$AJ:$AJ=$A28,'1'!$A:$A=$B28),1),""""))"),2200.0) -> 2200 | M28: =IFERROR(__xludf.DUMMYFUNCTION("IF($B28="""","""",IFERROR(INDEX(FILTER('1'!$AM:$AM,'1'!$AJ:$AJ=$A28,'1'!$A:$A=$B28),1),""""))"),7.0) -> 7 | N28: =F28 -> 4 | O28: =IFERROR(__xludf.DUMMYFUNCTION("IF($B28="""","""",IFERROR(INDEX(FILTER('1'!$AR:$AR,'1'!$AJ:$AJ=$A28,'1'!$A:$A=$B28),1),""""))"),0.0) -> 0 | P28: =IFERROR(__xludf.DUMMYFUNCTION("IF($B28="""","""",IFERROR(INDEX(FILTER('1'!$AS:$AS,'1'!$AJ:$AJ=$A28,'1'!$A:$A=$B28),1),""""))"),11.0) -> 11 | Q28: =IFERROR(__xludf.DUMMYFUNCTION("IF($B28="""","""",IFERROR(INDEX(FILTER('1'!$AU:$AU,'1'!$AJ:$AJ=$A28,'1'!$A:$A=$B28),1),""""))"),-1.0) -> -1
A29: 3 | B29: 46169 | C29: =IF(B29="","",TEXT(B29,"ddd")) -> 水 | D29: =IFERROR(__xludf.DUMMYFUNCTION("IF($B29="""","""",IFERROR(INDEX(FILTER('1'!$AK:$AK,'1'!$AJ:$AJ=$A29,'1'!$A:$A=$B29),1),""""))"),1166.0) -> 1166 | E29: =IFERROR(__xludf.DUMMYFUNCTION("IF($B29="""","""",IFERROR(INDEX(FILTER('1'!$AM:$AM,'1'!$AJ:$AJ=$A29,'1'!$A:$A=$B29),1),""""))"),1.0) -> 1 | F29: =IFERROR(__xludf.DUMMYFUNCTION("IF($B29="""","""",IFERROR(INDEX(FILTER('1'!$AN:$AN,'1'!$AJ:$AJ=$A29,'1'!$A:$A=$B29),1),""""))"),1.0) -> 1 | G29: =IF(COUNT(F23:F29)=0,"",SUM(F23:F29)/7) -> 0.57142857 | H29: =IFERROR(__xludf.DUMMYFUNCTION("IF($B29="""","""",IFERROR(INDEX(FILTER('1'!$AO:$AO,'1'!$AJ:$AJ=$A29,'1'!$A:$A=$B29),1),""""))"),4091.0) -> 4091 | I29: =IFERROR(__xludf.DUMMYFUNCTION("IF($B29="""","""",IFERROR(INDEX(FILTER('1'!$AP:$AP,'1'!$AJ:$AJ=$A29,'1'!$A:$A=$B29),1),""""))"),2484.0) -> 2484 | J29: =IFERROR(__xludf.DUMMYFUNCTION("IF($B29="""","""",IFERROR(INDEX(FILTER('1'!$AQ:$AQ,'1'!$AJ:$AJ=$A29,'1'!$A:$A=$B29),1),""""))"),-1600.0) -> -1600 | K29: {=SUM(IFERROR(VALUE(J23:J29),0))} -> -12600 | M29: =IFERROR(__xludf.DUMMYFUNCTION("IF($B29="""","""",IFERROR(INDEX(FILTER('1'!$AM:$AM,'1'!$AJ:$AJ=$A29,'1'!$A:$A=$B29),1),""""))"),1.0) -> 1 | N29: =F29 -> 1 | O29: =IFERROR(__xludf.DUMMYFUNCTION("IF($B29="""","""",IFERROR(INDEX(FILTER('1'!$AR:$AR,'1'!$AJ:$AJ=$A29,'1'!$A:$A=$B29),1),""""))"),2.5) -> 2.5 | P29: =IFERROR(__xludf.DUMMYFUNCTION("IF($B29="""","""",IFERROR(INDEX(FILTER('1'!$AS:$AS,'1'!$AJ:$AJ=$A29,'1'!$A:$A=$B29),1),""""))"),6.0) -> 6 | Q29: =IFERROR(__xludf.DUMMYFUNCTION("IF($B29="""","""",IFERROR(INDEX(FILTER('1'!$AU:$AU,'1'!$AJ:$AJ=$A29,'1'!$A:$A=$B29),1),""""))"),3.5) -> 3.5
A30: 3 | B30: 46170 | C30: =IF(B30="","",TEXT(B30,"ddd")) -> 木 | D30: =IFERROR(__xludf.DUMMYFUNCTION("IF($B30="""","""",IFERROR(INDEX(FILTER('1'!$AK:$AK,'1'!$AJ:$AJ=$A30,'1'!$A:$A=$B30),1),""""))"),1166.0) -> 1166 | E30: =IFERROR(__xludf.DUMMYFUNCTION("IF($B30="""","""",IFERROR(INDEX(FILTER('1'!$AM:$AM,'1'!$AJ:$AJ=$A30,'1'!$A:$A=$B30),1),""""))"),2.0) -> 2 | H30: =IFERROR(__xludf.DUMMYFUNCTION("IF($B30="""","""",IFERROR(INDEX(FILTER('2'!$AK:$AK,'2'!$AH:$AH=$A30,'2'!$A:$A=$B30),1),""""))"),"") | I30: =IFERROR(__xludf.DUMMYFUNCTION("IF($B30="""","""",IFERROR(INDEX(FILTER('2'!$AL:$AL,'2'!$AH:$AH=$A30,'2'!$A:$A=$B30),1),""""))"),"") | J30: =IFERROR(__xludf.DUMMYFUNCTION("IF($B30="""","""",IFERROR(INDEX(FILTER('2'!$AM:$AM,'2'!$AH:$AH=$A30,'2'!$A:$A=$B30),1),""""))"),"") | M30: =IFERROR(__xludf.DUMMYFUNCTION("IF($B30="""","""",IFERROR(INDEX(FILTER('1'!$AM:$AM,'1'!$AJ:$AJ=$A30,'1'!$A:$A=$B30),1),""""))"),2.0) -> 2 | N30: =F30 | O30: =IFERROR(__xludf.DUMMYFUNCTION("IF($B30="""","""",IFERROR(INDEX(FILTER('1'!$AR:$AR,'1'!$AJ:$AJ=$A30,'1'!$A:$A=$B30),1),""""))"),"") | P30: =IFERROR(__xludf.DUMMYFUNCTION("IF($B30="""","""",IFERROR(INDEX(FILTER('1'!$AS:$AS,'1'!$AJ:$AJ=$A30,'1'!$A:$A=$B30),1),""""))"),"") | Q30: =IFERROR(__xludf.DUMMYFUNCTION("IF($B30="""","""",IFERROR(INDEX(FILTER('1'!$AU:$AU,'1'!$AJ:$AJ=$A30,'1'!$A:$A=$B30),1),""""))"),0.0) -> 0 | R30: =D30 -> 1166
A31: 3 | N31: =F31
A32: 3 | C32: =IF(B32="","",TEXT(B32,"ddd")) | N32: =F32
A33: 4 | B33: 46163 | C33: =IF(B33="","",TEXT(B33,"ddd")) -> 木 | D33: =IFERROR(__xludf.DUMMYFUNCTION("IF($B33="""","""",IFERROR(INDEX(FILTER('1'!$BA:$BA,'1'!$AZ:$AZ=$A33,'1'!$A:$A=$B33),1),""""))"),1167.0) -> 1167 | E33: =IFERROR(__xludf.DUMMYFUNCTION("IF($B33="""","""",IFERROR(INDEX(FILTER('1'!$BC:$BC,'1'!$AZ:$AZ=$A33,'1'!$A:$A=$B33),1),""""))"),3.0) -> 3 | F33: =IFERROR(__xludf.DUMMYFUNCTION("IF($B33="""","""",IFERROR(INDEX(FILTER('1'!$BD:$BD,'1'!$AZ:$AZ=$A33,'1'!$A:$A=$B33),1),""""))"),4.0) -> 4 | H33: =IFERROR(__xludf.DUMMYFUNCTION("IF($B33="""","""",IFERROR(INDEX(FILTER('1'!$BE:$BE,'1'!$AZ:$AZ=$A33,'1'!$A:$A=$B33),1),""""))"),2395.0) -> 2395 | I33: =IFERROR(__xludf.DUMMYFUNCTION("IF($B33="""","""",IFERROR(INDEX(FILTER('1'!$BF:$BF,'1'!$AZ:$AZ=$A33,'1'!$A:$A=$B33),1),""""))"),6014.0) -> 6014 | J33: =IFERROR(__xludf.DUMMYFUNCTION("IF($B33="""","""",IFERROR(INDEX(FILTER('1'!$BG:$BG,'1'!$AZ:$AZ=$A33,'1'!$A:$A=$B33),1),""""))"),5800.0) -> 5800 | M33: =IFERROR(__xludf.DUMMYFUNCTION("IF($B33="""","""",IFERROR(INDEX(FILTER('1'!$BC:$BC,'1'!$AZ:$AZ=$A33,'1'!$A:$A=$B33),1),""""))"),3.0) -> 3 | N33: =F33 -> 4 | O33: =IFERROR(__xludf.DUMMYFUNCTION("IF($B33="""","""",IFERROR(INDEX(FILTER('1'!$BH:$BH,'1'!$AZ:$AZ=$A33,'1'!$A:$A=$B33),1),""""))"),3.0) -> 3 | P33: =IFERROR(__xludf.DUMMYFUNCTION("IF($B33="""","""",IFERROR(INDEX(FILTER('1'!$BI:$BI,'1'!$AZ:$AZ=$A33,'1'!$A:$A=$B33),1),""""))"),7.0) -> 7 | Q33: =IFERROR(__xludf.DUMMYFUNCTION("IF($B33="""","""",IFERROR(INDEX(FILTER('1'!$BK:$BK,'1'!$AZ:$AZ=$A33,'1'!$A:$A=$B33),1),""""))"),4.0) -> 4
A34: 4 | B34: 46164 | C34: =IF(B34="","",TEXT(B34,"ddd")) -> 金 | D34: =IFERROR(__xludf.DUMMYFUNCTION("IF($B34="""","""",IFERROR(INDEX(FILTER('1'!$BA:$BA,'1'!$AZ:$AZ=$A34,'1'!$A:$A=$B34),1),""""))"),1167.0) -> 1167 | E34: =IFERROR(__xludf.DUMMYFUNCTION("IF($B34="""","""",IFERROR(INDEX(FILTER('1'!$BC:$BC,'1'!$AZ:$AZ=$A34,'1'!$A:$A=$B34),1),""""))"),1.0) -> 1 | F34: =IFERROR(__xludf.DUMMYFUNCTION("IF($B34="""","""",IFERROR(INDEX(FILTER('1'!$BD:$BD,'1'!$AZ:$AZ=$A34,'1'!$A:$A=$B34),1),""""))"),1.0) -> 1 | H34: =IFERROR(__xludf.DUMMYFUNCTION("IF($B34="""","""",IFERROR(INDEX(FILTER('1'!$BE:$BE,'1'!$AZ:$AZ=$A34,'1'!$A:$A=$B34),1),""""))"),3729.0) -> 3729 | I34: =IFERROR(__xludf.DUMMYFUNCTION("IF($B34="""","""",IFERROR(INDEX(FILTER('1'!$BF:$BF,'1'!$AZ:$AZ=$A34,'1'!$A:$A=$B34),1),""""))"),1476.0) -> 1476 | J34: =IFERROR(__xludf.DUMMYFUNCTION("IF($B34="""","""",IFERROR(INDEX(FILTER('1'!$BG:$BG,'1'!$AZ:$AZ=$A34,'1'!$A:$A=$B34),1),""""))"),-1600.0) -> -1600 | M34: =IFERROR(__xludf.DUMMYFUNCTION("IF($B34="""","""",IFERROR(INDEX(FILTER('1'!$BC:$BC,'1'!$AZ:$AZ=$A34,'1'!$A:$A=$B34),1),""""))"),1.0) -> 1 | N34: =F34 -> 1 | O34: =IFERROR(__xludf.DUMMYFUNCTION("IF($B34="""","""",IFERROR(INDEX(FILTER('1'!$BH:$BH,'1'!$AZ:$AZ=$A34,'1'!$A:$A=$B34),1),""""))"),3.5) -> 3.5 | P34: =IFERROR(__xludf.DUMMYFUNCTION("IF($B34="""","""",IFERROR(INDEX(FILTER('1'!$BI:$BI,'1'!$AZ:$AZ=$A34,'1'!$A:$A=$B34),1),""""))"),4.0) -> 4 | Q34: =IFERROR(__xludf.DUMMYFUNCTION("IF($B34="""","""",IFERROR(INDEX(FILTER('1'!$BK:$BK,'1'!$AZ:$AZ=$A34,'1'!$A:$A=$B34),1),""""))"),5.5) -> 5.5
A35: 4 | B35: 46165 | C35: =IF(B35="","",TEXT(B35,"ddd")) -> 土 | D35: =IFERROR(__xludf.DUMMYFUNCTION("IF($B35="""","""",IFERROR(INDEX(FILTER('1'!$BA:$BA,'1'!$AZ:$AZ=$A35,'1'!$A:$A=$B35),1),""""))"),1167.0) -> 1167 | E35: =IFERROR(__xludf.DUMMYFUNCTION("IF($B35="""","""",IFERROR(INDEX(FILTER('1'!$BC:$BC,'1'!$AZ:$AZ=$A35,'1'!$A:$A=$B35),1),""""))"),2.0) -> 2 | F35: =IFERROR(__xludf.DUMMYFUNCTION("IF($B35="""","""",IFERROR(INDEX(FILTER('1'!$BD:$BD,'1'!$AZ:$AZ=$A35,'1'!$A:$A=$B35),1),""""))"),-1.0) -> -1 | H35: =IFERROR(__xludf.DUMMYFUNCTION("IF($B35="""","""",IFERROR(INDEX(FILTER('1'!$BE:$BE,'1'!$AZ:$AZ=$A35,'1'!$A:$A=$B35),1),""""))"),6555.0) -> 6555 | I35: =IFERROR(__xludf.DUMMYFUNCTION("IF($B35="""","""",IFERROR(INDEX(FILTER('1'!$BF:$BF,'1'!$AZ:$AZ=$A35,'1'!$A:$A=$B35),1),""""))"),1136.0) -> 1136 | J35: =IFERROR(__xludf.DUMMYFUNCTION("IF($B35="""","""",IFERROR(INDEX(FILTER('1'!$BG:$BG,'1'!$AZ:$AZ=$A35,'1'!$A:$A=$B35),1),""""))"),-3000.0) -> -3000 | M35: =IFERROR(__xludf.DUMMYFUNCTION("IF($B35="""","""",IFERROR(INDEX(FILTER('1'!$BC:$BC,'1'!$AZ:$AZ=$A35,'1'!$A:$A=$B35),1),""""))"),2.0) -> 2 | N35: =F35 -> -1 | O35: =IFERROR(__xludf.DUMMYFUNCTION("IF($B35="""","""",IFERROR(INDEX(FILTER('1'!$BH:$BH,'1'!$AZ:$AZ=$A35,'1'!$A:$A=$B35),1),""""))"),2.5) -> 2.5 | P35: =IFERROR(__xludf.DUMMYFUNCTION("IF($B35="""","""",IFERROR(INDEX(FILTER('1'!$BI:$BI,'1'!$AZ:$AZ=$A35,'1'!$A:$A=$B35),1),""""))"),6.0) -> 6 | Q35: =IFERROR(__xludf.DUMMYFUNCTION("IF($B35="""","""",IFERROR(INDEX(FILTER('1'!$BK:$BK,'1'!$AZ:$AZ=$A35,'1'!$A:$A=$B35),1),""""))"),3.5) -> 3.5
A36: 4 | B36: 46166 | C36: =IF(B36="","",TEXT(B36,"ddd")) -> 日 | D36: =IFERROR(__xludf.DUMMYFUNCTION("IF($B36="""","""",IFERROR(INDEX(FILTER('1'!$BA:$BA,'1'!$AZ:$AZ=$A36,'1'!$A:$A=$B36),1),""""))"),1167.0) -> 1167 | E36: =IFERROR(__xludf.DUMMYFUNCTION("IF($B36="""","""",IFERROR(INDEX(FILTER('1'!$BC:$BC,'1'!$AZ:$AZ=$A36,'1'!$A:$A=$B36),1),""""))"),3.0) -> 3 | F36: =IFERROR(__xludf.DUMMYFUNCTION("IF($B36="""","""",IFERROR(INDEX(FILTER('1'!$BD:$BD,'1'!$AZ:$AZ=$A36,'1'!$A:$A=$B36),1),""""))"),6.0) -> 6 | H36: =IFERROR(__xludf.DUMMYFUNCTION("IF($B36="""","""",IFERROR(INDEX(FILTER('1'!$BE:$BE,'1'!$AZ:$AZ=$A36,'1'!$A:$A=$B36),1),""""))"),8753.0) -> 8753 | I36: =IFERROR(__xludf.DUMMYFUNCTION("IF($B36="""","""",IFERROR(INDEX(FILTER('1'!$BF:$BF,'1'!$AZ:$AZ=$A36,'1'!$A:$A=$B36),1),""""))"),12005.0) -> 12005 | J36: =IFERROR(__xludf.DUMMYFUNCTION("IF($B36="""","""",IFERROR(INDEX(FILTER('1'!$BG:$BG,'1'!$AZ:$AZ=$A36,'1'!$A:$A=$B36),1),""""))"),10000.0) -> 10000 | M36: =IFERROR(__xludf.DUMMYFUNCTION("IF($B36="""","""",IFERROR(INDEX(FILTER('1'!$BC:$BC,'1'!$AZ:$AZ=$A36,'1'!$A:$A=$B36),1),""""))"),3.0) -> 3 | N36: =F36 -> 6 | O36: =IFERROR(__xludf.DUMMYFUNCTION("IF($B36="""","""",IFERROR(INDEX(FILTER('1'!$BH:$BH,'1'!$AZ:$AZ=$A36,'1'!$A:$A=$B36),1),""""))"),2.0) -> 2 | P36: =IFERROR(__xludf.DUMMYFUNCTION("IF($B36="""","""",IFERROR(INDEX(FILTER('1'!$BI:$BI,'1'!$AZ:$AZ=$A36,'1'!$A:$A=$B36),1),""""))"),11.0) -> 11 | Q36: =IFERROR(__xludf.DUMMYFUNCTION("IF($B36="""","""",IFERROR(INDEX(FILTER('1'!$BK:$BK,'1'!$AZ:$AZ=$A36,'1'!$A:$A=$B36),1),""""))"),1.0) -> 1
A37: 4 | B37: 46167 | C37: =IF(B37="","",TEXT(B37,"ddd")) -> 月 | D37: =IFERROR(__xludf.DUMMYFUNCTION("IF($B37="""","""",IFERROR(INDEX(FILTER('1'!$BA:$BA,'1'!$AZ:$AZ=$A37,'1'!$A:$A=$B37),1),""""))"),1167.0) -> 1167 | E37: =IFERROR(__xludf.DUMMYFUNCTION("IF($B37="""","""",IFERROR(INDEX(FILTER('1'!$BC:$BC,'1'!$AZ:$AZ=$A37,'1'!$A:$A=$B37),1),""""))"),1.0) -> 1 | F37: =IFERROR(__xludf.DUMMYFUNCTION("IF($B37="""","""",IFERROR(INDEX(FILTER('1'!$BD:$BD,'1'!$AZ:$AZ=$A37,'1'!$A:$A=$B37),1),""""))"),1.0) -> 1 | H37: =IFERROR(__xludf.DUMMYFUNCTION("IF($B37="""","""",IFERROR(INDEX(FILTER('1'!$BE:$BE,'1'!$AZ:$AZ=$A37,'1'!$A:$A=$B37),1),""""))"),1865.0) -> 1865 | I37: =IFERROR(__xludf.DUMMYFUNCTION("IF($B37="""","""",IFERROR(INDEX(FILTER('1'!$BF:$BF,'1'!$AZ:$AZ=$A37,'1'!$A:$A=$B37),1),""""))"),935.0) -> 935 | J37: =IFERROR(__xludf.DUMMYFUNCTION("IF($B37="""","""",IFERROR(INDEX(FILTER('1'!$BG:$BG,'1'!$AZ:$AZ=$A37,'1'!$A:$A=$B37),1),""""))"),-1500.0) -> -1500 | M37: =IFERROR(__xludf.DUMMYFUNCTION("IF($B37="""","""",IFERROR(INDEX(FILTER('1'!$BC:$BC,'1'!$AZ:$AZ=$A37,'1'!$A:$A=$B37),1),""""))"),1.0) -> 1 | N37: =F37 -> 1 | O37: =IFERROR(__xludf.DUMMYFUNCTION("IF($B37="""","""",IFERROR(INDEX(FILTER('1'!$BH:$BH,'1'!$AZ:$AZ=$A37,'1'!$A:$A=$B37),1),""""))"),2.5) -> 2.5 | P37: =IFERROR(__xludf.DUMMYFUNCTION("IF($B37="""","""",IFERROR(INDEX(FILTER('1'!$BI:$BI,'1'!$AZ:$AZ=$A37,'1'!$A:$A=$B37),1),""""))"),4.0) -> 4 | Q37: =IFERROR(__xludf.DUMMYFUNCTION("IF($B37="""","""",IFERROR(INDEX(FILTER('1'!$BK:$BK,'1'!$AZ:$AZ=$A37,'1'!$A:$A=$B37),1),""""))"),4.5) -> 4.5
A38: 4 | B38: 46168 | C38: =IF(B38="","",TEXT(B38,"ddd")) -> 火 | D38: =IFERROR(__xludf.DUMMYFUNCTION("IF($B38="""","""",IFERROR(INDEX(FILTER('1'!$BA:$BA,'1'!$AZ:$AZ=$A38,'1'!$A:$A=$B38),1),""""))"),1167.0) -> 1167 | E38: =IFERROR(__xludf.DUMMYFUNCTION("IF($B38="""","""",IFERROR(INDEX(FILTER('1'!$BC:$BC,'1'!$AZ:$AZ=$A38,'1'!$A:$A=$B38),1),""""))"),2.0) -> 2 | F38: =IFERROR(__xludf.DUMMYFUNCTION("IF($B38="""","""",IFERROR(INDEX(FILTER('1'!$BD:$BD,'1'!$AZ:$AZ=$A38,'1'!$A:$A=$B38),1),""""))"),-1.0) -> -1 | H38: =IFERROR(__xludf.DUMMYFUNCTION("IF($B38="""","""",IFERROR(INDEX(FILTER('1'!$BE:$BE,'1'!$AZ:$AZ=$A38,'1'!$A:$A=$B38),1),""""))"),6833.0) -> 6833 | I38: =IFERROR(__xludf.DUMMYFUNCTION("IF($B38="""","""",IFERROR(INDEX(FILTER('1'!$BF:$BF,'1'!$AZ:$AZ=$A38,'1'!$A:$A=$B38),1),""""))"),1910.0) -> 1910 | J38: =IFERROR(__xludf.DUMMYFUNCTION("IF($B38="""","""",IFERROR(INDEX(FILTER('1'!$BG:$BG,'1'!$AZ:$AZ=$A38,'1'!$A:$A=$B38),1),""""))"),-3000.0) -> -3000 | M38: =IFERROR(__xludf.DUMMYFUNCTION("IF($B38="""","""",IFERROR(INDEX(FILTER('1'!$BC:$BC,'1'!$AZ:$AZ=$A38,'1'!$A:$A=$B38),1),""""))"),2.0) -> 2 | N38: =F38 -> -1 | O38: =IFERROR(__xludf.DUMMYFUNCTION("IF($B38="""","""",IFERROR(INDEX(FILTER('1'!$BH:$BH,'1'!$AZ:$AZ=$A38,'1'!$A:$A=$B38),1),""""))"),3.0) -> 3 | P38: =IFERROR(__xludf.DUMMYFUNCTION("IF($B38="""","""",IFERROR(INDEX(FILTER('1'!$BI:$BI,'1'!$AZ:$AZ=$A38,'1'!$A:$A=$B38),1),""""))"),6.0) -> 6 | Q38: =IFERROR(__xludf.DUMMYFUNCTION("IF($B38="""","""",IFERROR(INDEX(FILTER('1'!$BK:$BK,'1'!$AZ:$AZ=$A38,'1'!$A:$A=$B38),1),""""))"),4.0) -> 4
A39: 4 | B39: 46169 | C39: =IF(B39="","",TEXT(B39,"ddd")) -> 水 | D39: =IFERROR(__xludf.DUMMYFUNCTION("IF($B39="""","""",IFERROR(INDEX(FILTER('1'!$BA:$BA,'1'!$AZ:$AZ=$A39,'1'!$A:$A=$B39),1),""""))"),1167.0) -> 1167 | E39: =IFERROR(__xludf.DUMMYFUNCTION("IF($B39="""","""",IFERROR(INDEX(FILTER('1'!$BC:$BC,'1'!$AZ:$AZ=$A39,'1'!$A:$A=$B39),1),""""))"),3.0) -> 3 | F39: =IFERROR(__xludf.DUMMYFUNCTION("IF($B39="""","""",IFERROR(INDEX(FILTER('1'!$BD:$BD,'1'!$AZ:$AZ=$A39,'1'!$A:$A=$B39),1),""""))"),-3.0) -> -3 | G39: =IF(COUNT(F33:F39)=0,"",SUM(F33:F39)/7) -> 1 | H39: =IFERROR(__xludf.DUMMYFUNCTION("IF($B39="""","""",IFERROR(INDEX(FILTER('1'!$BE:$BE,'1'!$AZ:$AZ=$A39,'1'!$A:$A=$B39),1),""""))"),2987.0) -> 2987 | I39: =IFERROR(__xludf.DUMMYFUNCTION("IF($B39="""","""",IFERROR(INDEX(FILTER('1'!$BF:$BF,'1'!$AZ:$AZ=$A39,'1'!$A:$A=$B39),1),""""))"),409.0) -> 409 | J39: =IFERROR(__xludf.DUMMYFUNCTION("IF($B39="""","""",IFERROR(INDEX(FILTER('1'!$BG:$BG,'1'!$AZ:$AZ=$A39,'1'!$A:$A=$B39),1),""""))"),-4000.0) -> -4000 | K39: {=SUM(IFERROR(VALUE(J33:J39),0))} -> 2700 | M39: =IFERROR(__xludf.DUMMYFUNCTION("IF($B39="""","""",IFERROR(INDEX(FILTER('1'!$BC:$BC,'1'!$AZ:$AZ=$A39,'1'!$A:$A=$B39),1),""""))"),3.0) -> 3 | N39: =F39 -> -3 | O39: =IFERROR(__xludf.DUMMYFUNCTION("IF($B39="""","""",IFERROR(INDEX(FILTER('1'!$BH:$BH,'1'!$AZ:$AZ=$A39,'1'!$A:$A=$B39),1),""""))"),3.0) -> 3 | P39: =IFERROR(__xludf.DUMMYFUNCTION("IF($B39="""","""",IFERROR(INDEX(FILTER('1'!$BI:$BI,'1'!$AZ:$AZ=$A39,'1'!$A:$A=$B39),1),""""))"),8.0) -> 8 | Q39: =IFERROR(__xludf.DUMMYFUNCTION("IF($B39="""","""",IFERROR(INDEX(FILTER('1'!$BK:$BK,'1'!$AZ:$AZ=$A39,'1'!$A:$A=$B39),1),""""))"),3.0) -> 3
A40: 4 | B40: 46170 | C40: =IF(B40="","",TEXT(B40,"ddd")) -> 木 | D40: =IFERROR(__xludf.DUMMYFUNCTION("IF($B40="""","""",IFERROR(INDEX(FILTER('1'!$BA:$BA,'1'!$AZ:$AZ=$A40,'1'!$A:$A=$B40),1),""""))"),1167.0) -> 1167 | E40: =IFERROR(__xludf.DUMMYFUNCTION("IF($B40="""","""",IFERROR(INDEX(FILTER('1'!$BC:$BC,'1'!$AZ:$AZ=$A40,'1'!$A:$A=$B40),1),""""))"),4.0) -> 4 | H40: =IFERROR(__xludf.DUMMYFUNCTION("IF($B40="""","""",IFERROR(INDEX(FILTER('2'!$AZ:$AZ,'2'!$AW:$AW=$A40,'2'!$A:$A=$B40),1),""""))"),"") | I40: =IFERROR(__xludf.DUMMYFUNCTION("IF($B40="""","""",IFERROR(INDEX(FILTER('2'!$BA:$BA,'2'!$AW:$AW=$A40,'2'!$A:$A=$B40),1),""""))"),"") | J40: =IFERROR(__xludf.DUMMYFUNCTION("IF($B40="""","""",IFERROR(INDEX(FILTER('2'!$BB:$BB,'2'!$AW:$AW=$A40,'2'!$A:$A=$B40),1),""""))"),"") | M40: =IFERROR(__xludf.DUMMYFUNCTION("IF($B40="""","""",IFERROR(INDEX(FILTER('1'!$BC:$BC,'1'!$AZ:$AZ=$A40,'1'!$A:$A=$B40),1),""""))"),4.0) -> 4 | N40: =F40 | O40: =IFERROR(__xludf.DUMMYFUNCTION("IF($B40="""","""",IFERROR(INDEX(FILTER('1'!$BH:$BH,'1'!$AZ:$AZ=$A40,'1'!$A:$A=$B40),1),""""))"),"") | P40: =IFERROR(__xludf.DUMMYFUNCTION("IF($B40="""","""",IFERROR(INDEX(FILTER('1'!$BI:$BI,'1'!$AZ:$AZ=$A40,'1'!$A:$A=$B40),1),""""))"),"") | Q40: =IFERROR(__xludf.DUMMYFUNCTION("IF($B40="""","""",IFERROR(INDEX(FILTER('1'!$BK:$BK,'1'!$AZ:$AZ=$A40,'1'!$A:$A=$B40),1),""""))"),0.0) -> 0 | R40: =D40 -> 1167
...

Sheet 前日
A1: ='1'!A1 -> GOD | M1: =A1 -> GOD
A2: 仮番号 | B2: 日付 | C2: 曜日 | D2: 台番号 | E2: 評価4以上の周期 | F2: 有効実績評価 | G2: 7日間有効実績評価平均 | H2: G数 | I2: 最大放出 | J2: 差枚 | K2: 7日間差枚 | M2: 評価4以上の周期 | N2: 実評価 | O2: AI予想 | P2: python順位 | Q2: 合算pt
A3: {=LET(n,20,TOCOL(MAKEARRAY(n,10,LAMBDA(r,c,r)),1))} -> 1 | B3: {=LET(d,SEQUENCE(8,1,TODAY()-7,1),TOCOL(MAKEARRAY(24,10,LAMBDA(r,c,IF(c<=8,INDEX(d,c),""))),1))} -> 46163 | C3: =IF(B3="","",TEXT(B3,"ddd")) -> 木 | D3: =IFERROR(__xludf.DUMMYFUNCTION("IF($B3="""","""",IFERROR(INDEX(FILTER('1'!$E:$E,'1'!$D:$D=$A3,'1'!$A:$A=$B3),1),""""))"),1164.0) -> 1164 | E3: =IFERROR(__xludf.DUMMYFUNCTION("IF($B3="""","""",IFERROR(INDEX(FILTER('1'!$G:$G,'1'!$D:$D=$A3,'1'!$A:$A=$B3),1),""""))"),5.0) -> 5 | F3: =IFERROR(__xludf.DUMMYFUNCTION("IF($B3="""","""",IFERROR(INDEX(FILTER('1'!$H:$H,'1'!$D:$D=$A3,'1'!$A:$A=$B3),1),""""))"),3.0) -> 3 | H3: =IFERROR(__xludf.DUMMYFUNCTION("IF($B3="""","""",IFERROR(INDEX(FILTER('1'!$I:$I,'1'!$D:$D=$A3,'1'!$A:$A=$B3),1),""""))"),8305.0) -> 8305 | I3: =IFERROR(__xludf.DUMMYFUNCTION("IF($B3="""","""",IFERROR(INDEX(FILTER('1'!$J:$J,'1'!$D:$D=$A3,'1'!$A:$A=$B3),1),""""))"),5331.0) -> 5331 | J3: =IFERROR(__xludf.DUMMYFUNCTION("IF($B3="""","""",IFERROR(INDEX(FILTER('1'!$K:$K,'1'!$D:$D=$A3,'1'!$A:$A=$B3),1),""""))"),800.0) -> 800 | M3: =IFERROR(__xludf.DUMMYFUNCTION("IF($B3="""","""",IFERROR(INDEX(FILTER('1'!$G:$G,'1'!$D:$D=$A3,'1'!$A:$A=$B3),1),""""))"),5.0) -> 5 | N3: =F3 -> 3 | O3: =IFERROR(__xludf.DUMMYFUNCTION("IF($B3="""","""",IFERROR(INDEX(FILTER('1'!$L:$L,'1'!$D:$D=$A3,'1'!$A:$A=$B3),1),""""))"),2.5) -> 2.5 | P3: =IFERROR(__xludf.DUMMYFUNCTION("IF($B3="""","""",IFERROR(INDEX(FILTER('1'!$M:$M,'1'!$D:$D=$A3,'1'!$A:$A=$B3),1),""""))"),6.0) -> 6 | Q3: =IFERROR(__xludf.DUMMYFUNCTION("IF($B3="""","""",IFERROR(INDEX(FILTER('1'!$O:$O,'1'!$D:$D=$A3,'1'!$A:$A=$B3),1),""""))"),3.5) -> 3.5
A4: 1 | B4: 46164 | C4: =IF(B4="","",TEXT(B4,"ddd")) -> 金 | D4: =IFERROR(__xludf.DUMMYFUNCTION("IF($B4="""","""",IFERROR(INDEX(FILTER('1'!$E:$E,'1'!$D:$D=$A4,'1'!$A:$A=$B4),1),""""))"),1164.0) -> 1164 | E4: =IFERROR(__xludf.DUMMYFUNCTION("IF($B4="""","""",IFERROR(INDEX(FILTER('1'!$G:$G,'1'!$D:$D=$A4,'1'!$A:$A=$B4),1),""""))"),6.0) -> 6 | F4: =IFERROR(__xludf.DUMMYFUNCTION("IF($B4="""","""",IFERROR(INDEX(FILTER('1'!$H:$H,'1'!$D:$D=$A4,'1'!$A:$A=$B4),1),""""))"),1.0) -> 1 | H4: =IFERROR(__xludf.DUMMYFUNCTION("IF($B4="""","""",IFERROR(INDEX(FILTER('1'!$I:$I,'1'!$D:$D=$A4,'1'!$A:$A=$B4),1),""""))"),5545.0) -> 5545 | I4: =IFERROR(__xludf.DUMMYFUNCTION("IF($B4="""","""",IFERROR(INDEX(FILTER('1'!$J:$J,'1'!$D:$D=$A4,'1'!$A:$A=$B4),1),""""))"),2034.0) -> 2034 | J4: =IFERROR(__xludf.DUMMYFUNCTION("IF($B4="""","""",IFERROR(INDEX(FILTER('1'!$K:$K,'1'!$D:$D=$A4,'1'!$A:$A=$B4),1),""""))"),-600.0) -> -600 | M4: =IFERROR(__xludf.DUMMYFUNCTION("IF($B4="""","""",IFERROR(INDEX(FILTER('1'!$G:$G,'1'!$D:$D=$A4,'1'!$A:$A=$B4),1),""""))"),6.0) -> 6 | N4: =F4 -> 1 | O4: =IFERROR(__xludf.DUMMYFUNCTION("IF($B4="""","""",IFERROR(INDEX(FILTER('1'!$L:$L,'1'!$D:$D=$A4,'1'!$A:$A=$B4),1),""""))"),2.0) -> 2 | P4: =IFERROR(__xludf.DUMMYFUNCTION("IF($B4="""","""",IFERROR(INDEX(FILTER('1'!$M:$M,'1'!$D:$D=$A4,'1'!$A:$A=$B4),1),""""))"),8.0) -> 8 | Q4: =IFERROR(__xludf.DUMMYFUNCTION("IF($B4="""","""",IFERROR(INDEX(FILTER('1'!$O:$O,'1'!$D:$D=$A4,'1'!$A:$A=$B4),1),""""))"),2.0) -> 2
A5: 1 | B5: 46165 | C5: =IF(B5="","",TEXT(B5,"ddd")) -> 土 | D5: =IFERROR(__xludf.DUMMYFUNCTION("IF($B5="""","""",IFERROR(INDEX(FILTER('1'!$E:$E,'1'!$D:$D=$A5,'1'!$A:$A=$B5),1),""""))"),1164.0) -> 1164 | E5: =IFERROR(__xludf.DUMMYFUNCTION("IF($B5="""","""",IFERROR(INDEX(FILTER('1'!$G:$G,'1'!$D:$D=$A5,'1'!$A:$A=$B5),1),""""))"),7.0) -> 7 | F5: =IFERROR(__xludf.DUMMYFUNCTION("IF($B5="""","""",IFERROR(INDEX(FILTER('1'!$H:$H,'1'!$D:$D=$A5,'1'!$A:$A=$B5),1),""""))"),4.0) -> 4 | H5: =IFERROR(__xludf.DUMMYFUNCTION("IF($B5="""","""",IFERROR(INDEX(FILTER('1'!$I:$I,'1'!$D:$D=$A5,'1'!$A:$A=$B5),1),""""))"),7505.0) -> 7505 | I5: =IFERROR(__xludf.DUMMYFUNCTION("IF($B5="""","""",IFERROR(INDEX(FILTER('1'!$J:$J,'1'!$D:$D=$A5,'1'!$A:$A=$B5),1),""""))"),5084.0) -> 5084 | J5: =IFERROR(__xludf.DUMMYFUNCTION("IF($B5="""","""",IFERROR(INDEX(FILTER('1'!$K:$K,'1'!$D:$D=$A5,'1'!$A:$A=$B5),1),""""))"),2100.0) -> 2100 | M5: =IFERROR(__xludf.DUMMYFUNCTION("IF($B5="""","""",IFERROR(INDEX(FILTER('1'!$G:$G,'1'!$D:$D=$A5,'1'!$A:$A=$B5),1),""""))"),7.0) -> 7 | N5: =F5 -> 4 | O5: =IFERROR(__xludf.DUMMYFUNCTION("IF($B5="""","""",IFERROR(INDEX(FILTER('1'!$L:$L,'1'!$D:$D=$A5,'1'!$A:$A=$B5),1),""""))"),2.0) -> 2 | P5: =IFERROR(__xludf.DUMMYFUNCTION("IF($B5="""","""",IFERROR(INDEX(FILTER('1'!$M:$M,'1'!$D:$D=$A5,'1'!$A:$A=$B5),1),""""))"),8.0) -> 8 | Q5: =IFERROR(__xludf.DUMMYFUNCTION("IF($B5="""","""",IFERROR(INDEX(FILTER('1'!$O:$O,'1'!$D:$D=$A5,'1'!$A:$A=$B5),1),""""))"),2.0) -> 2
A6: 1 | B6: 46166 | C6: =IF(B6="","",TEXT(B6,"ddd")) -> 日 | D6: =IFERROR(__xludf.DUMMYFUNCTION("IF($B6="""","""",IFERROR(INDEX(FILTER('1'!$E:$E,'1'!$D:$D=$A6,'1'!$A:$A=$B6),1),""""))"),1164.0) -> 1164 | E6: =IFERROR(__xludf.DUMMYFUNCTION("IF($B6="""","""",IFERROR(INDEX(FILTER('1'!$G:$G,'1'!$D:$D=$A6,'1'!$A:$A=$B6),1),""""))"),1.0) -> 1 | F6: =IFERROR(__xludf.DUMMYFUNCTION("IF($B6="""","""",IFERROR(INDEX(FILTER('1'!$H:$H,'1'!$D:$D=$A6,'1'!$A:$A=$B6),1),""""))"),-1.0) -> -1 | H6: =IFERROR(__xludf.DUMMYFUNCTION("IF($B6="""","""",IFERROR(INDEX(FILTER('1'!$I:$I,'1'!$D:$D=$A6,'1'!$A:$A=$B6),1),""""))"),7537.0) -> 7537 | I6: =IFERROR(__xludf.DUMMYFUNCTION("IF($B6="""","""",IFERROR(INDEX(FILTER('1'!$J:$J,'1'!$D:$D=$A6,'1'!$A:$A=$B6),1),""""))"),1921.0) -> 1921 | J6: =IFERROR(__xludf.DUMMYFUNCTION("IF($B6="""","""",IFERROR(INDEX(FILTER('1'!$K:$K,'1'!$D:$D=$A6,'1'!$A:$A=$B6),1),""""))"),-2500.0) -> -2500 | M6: =IFERROR(__xludf.DUMMYFUNCTION("IF($B6="""","""",IFERROR(INDEX(FILTER('1'!$G:$G,'1'!$D:$D=$A6,'1'!$A:$A=$B6),1),""""))"),1.0) -> 1 | N6: =F6 -> -1 | O6: =IFERROR(__xludf.DUMMYFUNCTION("IF($B6="""","""",IFERROR(INDEX(FILTER('1'!$L:$L,'1'!$D:$D=$A6,'1'!$A:$A=$B6),1),""""))"),3.0) -> 3 | P6: =IFERROR(__xludf.DUMMYFUNCTION("IF($B6="""","""",IFERROR(INDEX(FILTER('1'!$M:$M,'1'!$D:$D=$A6,'1'!$A:$A=$B6),1),""""))"),5.0) -> 5 | Q6: =IFERROR(__xludf.DUMMYFUNCTION("IF($B6="""","""",IFERROR(INDEX(FILTER('1'!$O:$O,'1'!$D:$D=$A6,'1'!$A:$A=$B6),1),""""))"),5.0) -> 5
A7: 1 | B7: 46167 | C7: =IF(B7="","",TEXT(B7,"ddd")) -> 月 | D7: =IFERROR(__xludf.DUMMYFUNCTION("IF($B7="""","""",IFERROR(INDEX(FILTER('1'!$E:$E,'1'!$D:$D=$A7,'1'!$A:$A=$B7),1),""""))"),1164.0) -> 1164 | E7: =IFERROR(__xludf.DUMMYFUNCTION("IF($B7="""","""",IFERROR(INDEX(FILTER('1'!$G:$G,'1'!$D:$D=$A7,'1'!$A:$A=$B7),1),""""))"),2.0) -> 2 | F7: =IFERROR(__xludf.DUMMYFUNCTION("IF($B7="""","""",IFERROR(INDEX(FILTER('1'!$H:$H,'1'!$D:$D=$A7,'1'!$A:$A=$B7),1),""""))"),-3.0) -> -3 | H7: =IFERROR(__xludf.DUMMYFUNCTION("IF($B7="""","""",IFERROR(INDEX(FILTER('1'!$I:$I,'1'!$D:$D=$A7,'1'!$A:$A=$B7),1),""""))"),7902.0) -> 7902 | I7: =IFERROR(__xludf.DUMMYFUNCTION("IF($B7="""","""",IFERROR(INDEX(FILTER('1'!$J:$J,'1'!$D:$D=$A7,'1'!$A:$A=$B7),1),""""))"),730.0) -> 730 | J7: =IFERROR(__xludf.DUMMYFUNCTION("IF($B7="""","""",IFERROR(INDEX(FILTER('1'!$K:$K,'1'!$D:$D=$A7,'1'!$A:$A=$B7),1),""""))"),-6000.0) -> -6000 | M7: =IFERROR(__xludf.DUMMYFUNCTION("IF($B7="""","""",IFERROR(INDEX(FILTER('1'!$G:$G,'1'!$D:$D=$A7,'1'!$A:$A=$B7),1),""""))"),2.0) -> 2 | N7: =F7 -> -3 | O7: =IFERROR(__xludf.DUMMYFUNCTION("IF($B7="""","""",IFERROR(INDEX(FILTER('1'!$L:$L,'1'!$D:$D=$A7,'1'!$A:$A=$B7),1),""""))"),1.5) -> 1.5 | P7: =IFERROR(__xludf.DUMMYFUNCTION("IF($B7="""","""",IFERROR(INDEX(FILTER('1'!$M:$M,'1'!$D:$D=$A7,'1'!$A:$A=$B7),1),""""))"),9.0) -> 9 | Q7: =IFERROR(__xludf.DUMMYFUNCTION("IF($B7="""","""",IFERROR(INDEX(FILTER('1'!$O:$O,'1'!$D:$D=$A7,'1'!$A:$A=$B7),1),""""))"),1.5) -> 1.5
A8: 1 | B8: 46168 | C8: =IF(B8="","",TEXT(B8,"ddd")) -> 火 | D8: =IFERROR(__xludf.DUMMYFUNCTION("IF($B8="""","""",IFERROR(INDEX(FILTER('1'!$E:$E,'1'!$D:$D=$A8,'1'!$A:$A=$B8),1),""""))"),1164.0) -> 1164 | E8: =IFERROR(__xludf.DUMMYFUNCTION("IF($B8="""","""",IFERROR(INDEX(FILTER('1'!$G:$G,'1'!$D:$D=$A8,'1'!$A:$A=$B8),1),""""))"),3.0) -> 3 | F8: =IFERROR(__xludf.DUMMYFUNCTION("IF($B8="""","""",IFERROR(INDEX(FILTER('1'!$H:$H,'1'!$D:$D=$A8,'1'!$A:$A=$B8),1),""""))"),-3.0) -> -3 | H8: =IFERROR(__xludf.DUMMYFUNCTION("IF($B8="""","""",IFERROR(INDEX(FILTER('1'!$I:$I,'1'!$D:$D=$A8,'1'!$A:$A=$B8),1),""""))"),6833.0) -> 6833 | I8: =IFERROR(__xludf.DUMMYFUNCTION("IF($B8="""","""",IFERROR(INDEX(FILTER('1'!$J:$J,'1'!$D:$D=$A8,'1'!$A:$A=$B8),1),""""))"),750.0) -> 750 | J8: =IFERROR(__xludf.DUMMYFUNCTION("IF($B8="""","""",IFERROR(INDEX(FILTER('1'!$K:$K,'1'!$D:$D=$A8,'1'!$A:$A=$B8),1),""""))"),-4500.0) -> -4500 | M8: =IFERROR(__xludf.DUMMYFUNCTION("IF($B8="""","""",IFERROR(INDEX(FILTER('1'!$G:$G,'1'!$D:$D=$A8,'1'!$A:$A=$B8),1),""""))"),3.0) -> 3 | N8: =F8 -> -3 | O8: =IFERROR(__xludf.DUMMYFUNCTION("IF($B8="""","""",IFERROR(INDEX(FILTER('1'!$L:$L,'1'!$D:$D=$A8,'1'!$A:$A=$B8),1),""""))"),0.5) -> 0.5 | P8: =IFERROR(__xludf.DUMMYFUNCTION("IF($B8="""","""",IFERROR(INDEX(FILTER('1'!$M:$M,'1'!$D:$D=$A8,'1'!$A:$A=$B8),1),""""))"),8.0) -> 8 | Q8: =IFERROR(__xludf.DUMMYFUNCTION("IF($B8="""","""",IFERROR(INDEX(FILTER('1'!$O:$O,'1'!$D:$D=$A8,'1'!$A:$A=$B8),1),""""))"),0.5) -> 0.5
